Workbook

Sheet Duración VALMER
A1: Fecha | B1: SB12AGO26 | C1: SB12AGO37 | D1: SB12AGO31 | E1: SB12FEB42 | F1: SB12FEB55 | G1: SB12AGO28 | H1: SB12AGO32 | I1: SB12FEB29 | J1: SB12AGO34 | K1: SB12AGO40 | L1: SB12AGO33 | M1: SB12AGO39 | N1: SB12AGO35
A2: 45747 | B2: 1.271545 | C2: 7.87006 | D2: 4.969056 | E2: 9.514059 | F2: 12.002098 | G2: 2.983172 | H2: 5.646549 | I2: 3.336802 | J2: 6.85791 | K2: 9.413615 | L2: 6.02346 | M2: 8.414499
A3: 45748 | B3: 1.268882 | C3: 7.867468 | D3: 4.966426 | E3: 9.51147 | F3: 11.9995 | G3: 2.980511 | H3: 5.64393 | I3: 3.334148 | J3: 6.855308 | K3: 9.411023 | L3: 6.02085 | M3: 8.411908
A4: 45749 | B4: 1.266469 | C4: 7.874356 | D4: 4.968514 | E4: 9.525512 | F4: 12.035261 | G4: 2.979204 | H4: 5.646185 | I4: 3.332277 | J4: 6.857011 | K4: 9.422448 | L4: 6.024319 | M4: 8.421542
A5: 45750 | B5: 1.264181 | C5: 7.893111 | D5: 4.973751 | E5: 9.55623 | F5: 12.109699 | G5: 2.978233 | H5: 5.65429 | I5: 3.331189 | J5: 6.870208 | K5: 9.444388 | L5: 6.031438 | M5: 8.440361
A6: 45751 | B6: 1.25656 | C6: 7.913805 | D6: 4.972146 | E6: 9.581796 | F6: 12.374855 | G6: 2.971256 | H6: 5.656177 | I6: 3.32557 | J6: 6.881066 | K6: 9.461158 | L6: 6.041855 | M6: 8.457068
A7: 45754 | B7: 1.254145 | C7: 7.892213 | D7: 4.965578 | E7: 9.537522 | F7: 12.27418 | G7: 2.969266 | H7: 5.648675 | I7: 3.323696 | J7: 6.869834 | K7: 9.423503 | L7: 6.033153 | M7: 8.423868
A8: 45755 | B8: 1.25123 | C8: 7.865896 | D8: 4.959013 | E8: 9.497486 | F8: 12.183884 | G8: 2.965926 | H8: 5.640204 | I8: 3.320257 | J8: 6.849996 | K8: 9.389382 | L8: 6.019592 | M8: 8.393774
A9: 45756 | B9: 1.248812 | C9: 7.834872 | D9: 4.957952 | E9: 9.449216 | F9: 12.074826 | G9: 2.963262 | H9: 5.636608 | I9: 3.317991 | J9: 6.837346 | K9: 9.348299 | L9: 6.007258 | M9: 8.357619
A10: 45757 | B10: 1.246394 | C10: 7.867814 | D10: 4.960819 | E10: 9.533904 | F10: 12.178685 | G10: 2.961945 | H10: 5.643727 | I10: 3.317677 | J10: 6.844783 | K10: 9.412219 | L10: 6.016796 | M10: 8.406918
A11: 45758 | B11: 1.237902 | C11: 7.8316 | D11: 4.948991 | E11: 9.48037 | F11: 12.064448 | G11: 2.952603 | H11: 5.630986 | I11: 3.308142 | J11: 6.821198 | K11: 9.365932 | L11: 5.994389 | M11: 8.36861
A12: 45761 | B12: 1.235114 | C12: 7.852688 | D12: 4.946357 | E12: 9.519365 | F12: 12.158587 | G12: 2.949603 | H12: 5.630309 | I12: 3.305095 | J12: 6.834361 | K12: 9.398345 | L12: 6.000271 | M12: 8.396548
A13: 45762 | B13: 1.232449 | C13: 7.850093 | D13: 4.943724 | E13: 9.51677 | F13: 12.155986 | G13: 2.946939 | H13: 5.627686 | I13: 3.302438 | J13: 6.831755 | K13: 9.395752 | L13: 5.99766 | M13: 8.393955
... A65: 45839 | B65: 1.035182 | C65: 7.962219 | D65: 4.882706 | E65: 9.627469 | F65: 12.461631 | G65: 2.765615 | H65: 5.671096 | I65: 3.172362 | J65: 6.887571 | K65: 9.584169 | L65: 6.016914 | M65: 8.539011
A66: 45840 | B66: 1.032584 | C66: 7.962534 | D66: 4.880134 | E66: 9.630109 | F66: 12.445287 | G66: 2.763439 | H66: 5.669709 | I66: 3.170113 | J66: 6.888756 | K66: 9.580256 | L66: 6.015509 | M66: 8.536086 | N66: 7.327964
A67: 45841 | B67: 1.029784 | C67: 7.958743 | D67: 4.878955 | E67: 9.62664 | F67: 12.441814 | G67: 2.760706 | H67: 5.668324 | I67: 3.169559 | J67: 6.888058 | K67: 9.577194 | L67: 6.013894 | M67: 8.531305 | N67: 7.327964
A68: 45842 | B68: 1.02178 | C68: 7.951084 | D68: 4.871182 | E68: 9.618691 | F68: 12.434221 | G68: 2.752683 | H68: 5.66023 | I68: 3.161679 | J68: 6.880266 | K68: 9.569476 | L68: 6.006185 | M68: 8.523704 | N68: 7.32636
A69: 45845 | B69: 1.0204563 | C69: 7.9489468 | D69: 4.8725795 | E69: 9.6106472 | F69: 12.41197 | G69: 2.7510578 | H69: 5.660876 | I69: 3.1607765 | J69: 6.878777 | K69: 9.5678338 | L69: 6.0059633 | M69: 8.5221055 | N69: 7.3168537
A70: 45846 | B70: 1.0165305 | C70: 7.9448755 | D70: 4.87068 | E70: 9.6003635 | F70: 12.387659 | G70: 2.7467875 | H70: 5.6581675 | I70: 3.156211 | J70: 6.873741 | K70: 9.5638635 | L70: 6.0026945 | M70: 8.519097 | N70: 7.3112986
A71: 45847 | B71: 1.0111285 | C71: 7.9391505 | D71: 4.866204 | E71: 9.5946545 | F71: 12.382127 | G71: 2.7414095 | H71: 5.653428 | I71: 3.151994 | J71: 6.869496 | K71: 9.5584735 | L71: 5.9980325 | M71: 8.512906 | N71: 7.3057435
A72: 45848 | B72: 1.0085038 | C72: 7.9360463 | D72: 4.865953 | E72: 9.5854907 | F72: 12.358846 | G72: 2.7384617 | H72: 5.6523968 | I72: 3.14926 | J72: 6.8662335 | K72: 9.5556672 | L72: 5.9962872 | M72: 8.5106025 | N72: 7.3057435
A73: 45849 | B73: 1.0044904 | C73: 7.9316316 | D73: 4.8635895 | E73: 9.5780544 | F73: 12.344439 | G73: 2.7342989 | H73: 5.6495114 | I73: 3.1457845 | J73: 6.8624798 | K73: 9.5515691 | L73: 5.9930836 | M73: 8.5063552 | N73: 7.3057435
A74: 45852 | B74: 1.000477 | C74: 7.927217 | D74: 4.861226 | E74: 9.570618 | F74: 12.330032 | G74: 2.730136 | H74: 5.646626 | I74: 3.142309 | J74: 6.858726 | K74: 9.547471 | L74: 5.98988 | M74: 8.502108 | N74: 7.285127
A75: 45853 | B75: 0.997828 | C75: 7.918499 | D75: 4.858132 | E75: 9.570132 | F75: 12.333179 | G75: 2.730904 | H75: 5.642539 | I75: 3.139921 | J75: 6.853975 | K75: 9.538137 | L75: 5.986984 | M75: 8.49443 | N75: 7.276419
A76: 45854 | B76: 0.995114 | C76: 7.908691 | D76: 4.856424 | E76: 9.562787 | F76: 12.32839 | G76: 2.728069 | H76: 5.640549 | I76: 3.136918 | J76: 6.852092 | K76: 9.530976 | L76: 5.983276 | M76: 8.487614 | N76: 7.267956
A77: 45855 | B77: 0.992383 | C77: 7.89654 | D77: 4.853228 | E77: 9.557067 | F77: 12.322631 | G77: 2.725353 | H77: 5.636393 | I77: 3.134137 | J77: 6.846442 | K77: 9.518811 | L77: 5.978933 | M77: 8.475656 | N77: 7.262173
... A173: 45994 | B173: 0.655289 | C173: 7.907666 | D173: 4.647359 | E173: 9.67648 | F173: 12.813018 | G173: 2.426388 | H173: 5.467497 | I173: 2.847964 | J173: 6.732964 | K173: 9.597477 | L173: 5.864681 | M173: 8.53121 | N173: 6.981985
A174: 45995 | C174: 7.907545 | D174: 4.644725 | E174: 9.673986 | F174: 12.820222 | G174: 2.423665 | H174: 5.464871 | I174: 2.845312 | J174: 6.732301 | K174: 9.598217 | L174: 5.86433 | M174: 8.529997 | N174: 6.980939
A175: 45996 | B175: 0.644477 | C175: 7.902779 | D175: 4.637848 | E175: 9.673984 | F175: 12.814722 | G175: 2.415591 | H175: 5.458541 | I175: 2.837425 | J175: 6.726348 | K175: 9.596303 | L175: 5.858027 | M175: 8.526576 | N175: 6.97804
A176: 46001 | B176: 0.639203 | C176: 7.902147 | D176: 4.633198 | E176: 9.680203 | F176: 12.833805 | G176: 2.410314 | H176: 5.454437 | I176: 2.832874 | J176: 6.72573 | K176: 9.600799 | L176: 5.856039 | M176: 8.531738 | N176: 6.9774
A177: 46002 | B177: 0.625508 | C177: 7.890241 | D177: 4.620275 | E177: 9.670118 | F177: 12.824686 | G177: 2.396798 | H177: 5.441892 | I177: 2.819975 | J177: 6.712056 | K177: 9.593123 | L177: 5.843582 | M177: 8.529614 | N177: 6.960607
A178: 46003 | B178: 0.625508 | C178: 7.890241 | D178: 4.620275 | E178: 9.670118 | F178: 12.824686 | G178: 2.396798 | H178: 5.441892 | I178: 2.819975 | J178: 6.712056 | K178: 9.593123 | L178: 5.843582 | M178: 8.529614 | N178: 6.960607
A179: 46006 | B179: 0.623159 | C179: 7.889333 | D179: 4.618848 | E179: 9.676041 | F179: 12.858769 | G179: 2.39531 | H179: 5.440466 | I179: 2.817615 | J179: 6.712545 | K179: 9.588959 | L179: 5.84703 | M179: 8.529807 | N179: 6.964519
A180: 46007 | B180: 0.620456 | C180: 7.88509 | D180: 4.61662 | E180: 9.676093 | F180: 12.862162 | G180: 2.392892 | H180: 5.438632 | I180: 2.815086 | J180: 6.714651 | K180: 9.584045 | L180: 5.845202 | M180: 8.525768 | N180: 6.966411
A181: 46008 | C181: 7.885337 | D181: 4.614816 | E181: 9.677242 | F181: 12.859433 | G181: 2.39003 | H181: 5.43719 | I181: 2.812192 | J181: 6.71554 | K181: 9.5855 | L181: 5.850745 | M181: 8.526095 | N181: 6.966627
A182: 46009 | B182: 0.614949 | C182: 7.881284 | D182: 4.612176 | E182: 9.676873 | F182: 12.866965 | G182: 2.386487 | H182: 5.434154 | I182: 2.809235 | J182: 6.711988 | K182: 9.583258 | L182: 5.847763 | M182: 8.521167 | N182: 6.960771
A183: 46010 | B183: 0.614949 | C183: 7.881284 | D183: 4.612176 | E183: 9.676873 | F183: 12.866965 | G183: 2.386487 | H183: 5.434154 | I183: 2.809235 | J183: 6.711988 | K183: 9.583258 | L183: 5.847763 | M183: 8.521167 | N183: 6.960771
A184: 46013 | B184: 0.604184 | C184: 7.859731 | D184: 4.600053 | E184: 9.650463 | F184: 12.820707 | G184: 2.375052 | H184: 5.418653 | I184: 2.798598 | J184: 6.70351 | K184: 9.556249 | L184: 5.82573 | M184: 8.499706 | N184: 6.931158
A185: 46014 | B185: 0.601395 | C185: 7.841844 | D185: 4.595693 | E185: 9.62665 | F185: 12.784432 | G185: 2.372603 | H185: 5.41154 | I185: 2.795782 | J185: 6.695291 | K185: 9.530219 | L185: 5.818914 | M185: 8.473008 | N185: 6.930412
A186: 46015 | B186: 0.596217 | C186: 7.835577 | D186: 4.592068 | E186: 9.6319 | F186: 12.81366 | G186: 2.366974 | H186: 5.40907 | I186: 2.790664 | J186: 6.687042 | K186: 9.519327 | L186: 5.816147 | M186: 8.476464 | N186: 6.931605
...

Sheet YTM VALMER
A1: Fecha | B1: SB12AGO26 | C1: SB12AGO37 | D1: SB12AGO31 | E1: SB12FEB42 | F1: SB12FEB55 | G1: SB12AGO28 | H1: SB12AGO32 | I1: SB12FEB29 | J1: SB12AGO34 | K1: SB12AGO40 | L1: SB12AGO33 | M1: SB12AGO39 | N1: SB12AGO35
A2: 45747
A3: 45748 | B3: 4.1734615 | C3: 7.0717188 | D3: 5.6189048 | E3: 7.1611951 | F3: 6.9590737 | G3: 4.3 | H3: 6.0451638 | I3: 4.67 | J3: 6.6880323 | K3: 7.2224451 | L3: 6.409697 | M3: 7.2180986
A4: 45749 | B4: 4.1734615 | C4: 7.02425 | D4: 5.5714516 | E4: 7.1058929 | F4: 6.9037715 | G4: 4.3 | H4: 6.0045946 | I4: 4.63 | J4: 6.6498174 | K4: 7.1671429 | L4: 6.375303 | M4: 7.1846134
A5: 45750 | B5: 4.0974615 | C5: 6.85 | D5: 5.4370778 | E5: 6.99 | F5: 6.6 | G5: 4.224 | H5: 5.8512096 | I5: 4.56 | J5: 6.4722678 | K5: 7.0635929 | L5: 6.1999 | M5: 7.0647039
A6: 45751 | B6: 4.0734615 | C6: 6.8013247 | D6: 5.4147541 | E6: 6.995 | F6: 6.605 | G6: 4.2 | H6: 5.7913953 | I6: 4.51 | J6: 6.3929938 | K6: 7.0371429 | L6: 6.1469704 | M6: 7.0236052
A7: 45754 | B7: 4.0634615 | C7: 6.9451707 | D7: 5.4446481 | E7: 7.1065226 | F7: 6.55 | G7: 4.19 | H7: 5.8693311 | I7: 4.51 | J7: 6.5295175 | K7: 7.1486654 | L7: 6.2228571 | M7: 7.16
A8: 45755 | B8: 4.0384615 | C8: 7.005102 | D8: 5.4454687 | E8: 7.2 | F8: 6.6434774 | G8: 4.165 | H8: 5.8701818 | I8: 4.5 | J8: 6.571874 | K8: 7.225 | L8: 6.3211402 | M8: 7.213617
A9: 45756 | B9: 4.0584615 | C9: 7.0890909 | D9: 5.465 | E9: 7.1 | F9: 6.5434774 | G9: 4.185 | H9: 5.9144444 | I9: 4.44 | J9: 6.6743478 | K9: 7.126999 | L9: 6.3433333 | M9: 7.2324165
A10: 45757 | B10: 4.0784615 | C10: 7.02 | D10: 5.45 | E10: 7.1 | F10: 6.5434774 | G10: 4.205 | H10: 5.87 | I10: 4.48 | J10: 6.6364583 | K10: 7.2 | L10: 6.32 | M10: 7.1979167
A11: 45758 | B11: 4.0834615 | C11: 7.0638636 | D11: 5.4898177 | E11: 7.1 | F11: 6.5434774 | G11: 4.21 | H11: 5.8989706 | I11: 4.485 | J11: 6.6543633 | K11: 7.185 | L11: 6.3656 | M11: 7.199829
A12: 45761 | B12: 4.0634615 | C12: 6.9595866 | D12: 5.456761 | E12: 7.085 | F12: 6.5284774 | G12: 4.19 | H12: 5.8763087 | I12: 4.492 | J12: 6.612062 | K12: 7.17 | L12: 6.3131767 | M12: 7.1623968
A13: 45762 | B13: 4.0734615 | C13: 7.0053067 | D13: 5.48 | E13: 7.091 | F13: 6.5344774 | G13: 4.2 | H13: 5.8517526 | I13: 4.53 | J13: 6.6268534 | K13: 7.176 | L13: 6.305 | M13: 7.1882222
A14: 45763 | B14: 4.0877473 | C14: 7.025 | D14: 5.49 | E14: 7.11 | F14: 6.5534774 | G14: 4.2142857 | H14: 5.88 | I14: 4.5533333 | J14: 6.6364912 | K14: 7.2166667 | L14: 6.3116 | M14: 7.2163348
... A64: 45838 | B64: 4.04 | C64: 6.68 | D64: 5.27 | E64: 6.75 | F64: 6.8 | G64: 3.95 | H64: 5.57 | I64: 4.45 | J64: 6.2 | K64: 6.9 | L64: 5.88 | M64: 6.89
A65: 45839 | B65: 3.99 | C65: 6.665625 | D65: 5.2330997 | E65: 6.765 | F65: 6.775 | G65: 3.9 | H65: 5.5420395 | I65: 4.32 | J65: 6.16 | K65: 6.88 | L65: 5.8583333 | M65: 6.8867304 | N65: 6.402951
A66: 45840 | B66: 3.99 | C66: 6.6874766 | D66: 5.1683333 | E66: 6.805 | F66: 6.775 | G66: 3.9 | H66: 5.4862826 | I66: 4.26 | J66: 6.1177433 | K66: 6.89 | L66: 5.8086667 | M66: 6.8845918 | N66: 6.3825601
A67: 45841 | B67: 4.08 | C67: 6.7072851 | D67: 5.1166667 | E67: 6.8 | F67: 6.8 | G67: 3.99 | H67: 5.4666414 | I67: 4.27 | J67: 6.135 | K67: 6.925 | L67: 5.8424074 | M67: 6.9277778 | N67: 6.3772436
A68: 45842 | B68: 4 | C68: 6.6856185 | D68: 5.0978947 | E68: 6.8 | F68: 6.835 | G68: 4.005 | H68: 5.47 | I68: 4.27 | J68: 6.125641 | K68: 6.902 | L68: 5.8464706 | M68: 6.9011111 | N68: 6.3459524
A69: 45845 | B69: 4 | C69: 6.7212594 | D69: 5.0842857 | E69: 6.8 | F69: 6.845 | G69: 4.005 | H69: 5.487561 | I69: 4.27 | J69: 6.1441041 | K69: 6.9216764 | L69: 5.8678395 | M69: 6.9276331 | N69: 6.3872888
A70: 45846 | B70: 3.9464658 | C70: 6.7358071 | D70: 5.0457143 | E70: 6.84 | F70: 6.84 | G70: 3.9514658 | H70: 5.4658333 | I70: 4.22 | J70: 6.149 | K70: 6.9198753 | L70: 5.8507368 | M70: 6.9182301 | N70: 6.4171246
A71: 45847 | B71: 4.025 | C71: 6.6796238 | D71: 5.03 | E71: 6.8 | F71: 6.84 | G71: 4.03 | H71: 5.4223684 | I71: 4.22 | J71: 6.1282796 | K71: 6.8641667 | L71: 5.8209434 | M71: 6.8683333 | N71: 6.3955952
A72: 45848 | B72: 4.0572785 | C72: 6.68625 | D72: 5.0436364 | E72: 6.8 | F72: 6.855 | G72: 4.0622785 | H72: 5.4446154 | I72: 4.24 | J72: 6.145 | K72: 6.8583333 | L72: 5.8359259 | M72: 6.84 | N72: 6.4230252
A73: 45849 | B73: 4.0453737 | C73: 6.7149551 | D73: 5.0045369 | E73: 6.83 | F73: 6.85 | G73: 4.0503737 | H73: 5.4062222 | I73: 4.23 | J73: 6.1654545 | K73: 6.8902247 | L73: 5.8309756 | M73: 6.8920253 | N73: 6.4449282
A74: 45852 | B74: 4.0187071 | C74: 6.7026437 | D74: 5.0053968 | E74: 6.84 | F74: 6.855 | G74: 4.0237071 | H74: 5.4026923 | I74: 4.2 | J74: 6.1752459 | K74: 6.9034391 | L74: 5.8385106 | M74: 6.9005882 | N74: 6.4625
A75: 45853 | B75: 4.028707 | C75: 6.7718182 | D75: 5.022 | E75: 6.83 | F75: 6.84 | G75: 4.0337071 | H75: 5.4506667 | I75: 4.21 | J75: 6.235261 | K75: 6.9460976 | L75: 5.8916337 | M75: 6.9475 | N75: 6.5201784
A76: 45854 | B76: 4.0187071 | C76: 6.815 | D76: 5.01 | E76: 6.8833333 | F76: 6.845 | G76: 4.0237071 | H76: 5.4471787 | I76: 4.2 | J76: 6.2667442 | K76: 6.9750969 | L76: 5.8959091 | M76: 6.9764286 | N76: 6.53625
... A216: 46059 | B216: 4.039002 | C216: 6.199025 | D216: 4.378097 | E216: 6.160507 | F216: 6.147777 | G216: 3.991462 | H216: 4.591898 | I216: 4.060543 | J216: 5.362453 | K216: 6.427712 | L216: 4.932373 | M216: 6.459928 | N216: 5.783816
A217: 46062 | C217: 6.212496 | D217: 4.373056 | E217: 6.160777 | F217: 6.156653 | G217: 3.93 | H217: 4.581531 | I217: 4.054174 | J217: 5.369392 | K217: 6.434304 | L217: 4.938288 | M217: 6.458432 | N217: 5.809072
A218: 46063 | B218: 4.007734 | C218: 6.2146509 | D218: 4.3611054 | E218: 6.1537386 | F218: 6.1519691 | G218: 3.9661752 | H218: 4.5689092 | I218: 4.0522471 | J218: 5.3804236 | K218: 6.4396517 | L218: 4.9493184 | M218: 6.4568565 | N218: 5.8077409
A219: 46064 | B219: 4.0063088 | C219: 6.2258431 | D219: 4.3730395 | E219: 6.1565654 | F219: 6.1517491 | G219: 3.9730462 | H219: 4.5650677 | I219: 4.0462262 | J219: 5.3875672 | K219: 6.4500439 | L219: 4.9465109 | M219: 6.469384 | N219: 5.818321
A220: 46065 | B220: 4.047178 | C220: 6.233875 | D220: 4.370194 | E220: 6.160266 | F220: 6.158509 | G220: 3.97349 | H220: 4.568575 | I220: 4.049996 | J220: 5.413468 | K220: 6.466961 | L220: 4.963245 | M220: 6.473764 | N220: 5.82328
A221: 46066 | B221: 4.023629 | C221: 6.238467 | D221: 4.374505 | E221: 6.157347 | F221: 6.157534 | G221: 3.973736 | H221: 4.571398 | I221: 4.065365 | J221: 5.417758 | K221: 6.465307 | L221: 4.952922 | M221: 6.483412 | N221: 5.812157
A222: 46069 | B222: 3.952535 | C222: 6.238046 | D222: 4.37116 | E222: 6.157022 | F222: 6.157421 | G222: 3.966131 | H222: 4.569671 | I222: 4.06043 | J222: 5.417686 | K222: 6.465647 | L222: 4.950824 | M222: 6.4829 | N222: 5.811409
A223: 46070 | B223: 4.038167 | C223: 6.23573 | D223: 4.371645 | E223: 6.151963 | F223: 6.154484 | G223: 3.967071 | H223: 4.565727 | I223: 4.048241 | J223: 5.402726 | K223: 6.457508 | L223: 4.937575 | M223: 6.476485 | N223: 5.778703
A224: 46071 | B224: 4.021421 | C224: 6.245152 | D224: 4.375459 | E224: 6.188334 | F224: 6.183901 | G224: 3.979216 | H224: 4.58192 | I224: 4.031546 | J224: 5.382891 | K224: 6.484121 | L224: 4.90452 | M224: 6.482776 | N224: 5.778056
A225: 46072 | B225: 4.034737 | C225: 6.240965 | D225: 4.373301 | E225: 6.174041 | F225: 6.175362 | G225: 3.969883 | H225: 4.576426 | I225: 4.027041 | J225: 5.390061 | K225: 6.480535 | L225: 4.900259 | M225: 6.47966 | N225: 5.808171
A226: 46073 | B226: 4.0347372 | C226: 6.25483 | D226: 4.396587 | E226: 6.178187 | F226: 6.176186 | G226: 3.9698831 | H226: 4.593463 | I226: 4.03868 | J226: 5.389454 | K226: 6.504427 | L226: 4.897697 | M226: 6.490174 | N226: 5.822092
A227: 46076 | B227: 3.99708 | C227: 6.249542 | D227: 4.407415 | E227: 6.190838 | F227: 6.180214 | G227: 3.959223 | H227: 4.612097 | I227: 4.034361 | J227: 5.392631 | K227: 6.513322 | L227: 4.908509 | M227: 6.502043 | N227: 5.809277
A228: 46077 | B228: 3.98893 | C228: 6.24257 | D228: 4.414069 | E228: 6.193369 | F228: 6.182524 | G228: 3.960678 | H228: 4.617981 | I228: 4.033574 | J228: 5.399205 | K228: 6.517777 | L228: 4.916112 | M228: 6.504005 | N228: 5.806405
...

Sheet Duración MEF
A1: Fecha | B1: SB12AGO26 | C1: SB12AGO28 | D1: SB12FEB29 | E1: SB12AGO31 | F1: SB12AGO32 | G1: SB12AGO33 | H1: SB12AGO34 | I1: SB12AGO35 | J1: SB12AGO37 | K1: SB12AGO39 | L1: SB12AGO40 | M1: SB12FEB42 | N1: SB12FEB55
A2: 45839 | B2: 1.03 | C2: 2.76 | D2: 3.16 | E2: 4.83 | F2: 5.54 | G2: 5.94 | H2: 6.79 | I2: 7.14 | J2: 7.83 | K2: 8.38 | L2: 9.41 | M2: 9.46 | N2: 12.19
A3: 45840 | B3: 1.03 | C3: 2.76 | D3: 3.16 | E3: 4.84 | F3: 5.54 | G3: 5.94 | H3: 6.79 | I3: 7.14 | J3: 7.82 | K3: 8.38 | L3: 9.4 | M3: 9.46 | N3: 12.17
A4: 45841 | B4: 1.03 | C4: 2.75 | D4: 3.16 | E4: 4.84 | F4: 5.54 | G4: 5.94 | H4: 6.79 | I4: 7.14 | J4: 7.81 | K4: 8.36 | L4: 9.38 | M4: 9.44 | N4: 12.17
A5: 45842 | B5: 1.02 | C5: 2.74 | D5: 3.15 | E5: 4.84 | F5: 5.54 | G5: 5.93 | H5: 6.79 | I5: 7.14 | J5: 7.82 | K5: 8.37 | L5: 9.39 | M5: 9.45 | N5: 12.13
A6: 45845 | B6: 1.02 | C6: 2.74 | D6: 3.15 | E6: 4.83 | F6: 5.53 | G6: 5.92 | H6: 6.78 | I6: 7.13 | J6: 7.8 | K6: 8.35 | L6: 9.38 | M6: 9.43 | N6: 12.11
A7: 45846 | B7: 1.01 | C7: 2.74 | D7: 3.15 | E7: 4.83 | F7: 5.53 | G7: 5.92 | H7: 6.77 | I7: 7.12 | J7: 7.79 | K7: 8.35 | L7: 9.37 | M7: 9.4 | N7: 12.1
A8: 45847 | B8: 1.01 | C8: 2.73 | D8: 3.14 | E8: 4.83 | F8: 5.53 | G8: 5.92 | H8: 6.77 | I8: 7.12 | J8: 7.81 | K8: 8.36 | L8: 9.39 | M8: 9.42 | N8: 12.12
A9: 45848 | B9: 1.01 | C9: 2.73 | D9: 3.14 | E9: 4.82 | F9: 5.53 | G9: 5.92 | H9: 6.77 | I9: 7.11 | J9: 7.8 | K9: 8.37 | L9: 9.39 | M9: 9.41 | N9: 12.1
A10: 45849 | B10: 1.01 | C10: 2.72 | D10: 3.14 | E10: 4.82 | F10: 5.53 | G10: 5.92 | H10: 6.76 | I10: 7.11 | J10: 7.79 | K10: 8.35 | L10: 9.38 | M10: 9.4 | N10: 12.1
A11: 45852 | B11: 1 | C11: 2.72 | D11: 3.13 | E11: 4.82 | F11: 5.52 | G11: 5.91 | H11: 6.75 | I11: 7.1 | J11: 7.78 | K11: 8.34 | L11: 9.36 | M11: 9.38 | N11: 12.09
A12: 45853 | B12: 1 | C12: 2.71 | D12: 3.13 | E12: 4.81 | F12: 5.51 | G12: 5.9 | H12: 6.74 | I12: 7.09 | J12: 7.77 | K12: 8.33 | L12: 9.34 | M12: 9.36 | N12: 12.1
A13: 45854 | B13: 0.99 | C13: 2.71 | D13: 3.13 | E13: 4.81 | F13: 5.51 | G13: 5.9 | H13: 6.74 | I13: 7.08 | J13: 7.76 | K13: 8.31 | L13: 9.34 | M13: 9.36 | N13: 12.1
... A24: 45874 | B24: 0.94 | C24: 2.66 | D24: 3.07 | E24: 4.76 | F24: 5.47 | G24: 5.86 | H24: 6.71 | I24: 7.06 | J24: 7.75 | K24: 8.32 | L24: 9.35 | M24: 9.37 | N24: 12.15
A25: 45875
A26: 45876 | B26: 0.93 | C26: 2.65 | D26: 3.07 | E26: 4.75 | F26: 5.47 | G26: 5.86 | H26: 6.72 | I26: 7.06 | J26: 7.75 | K26: 8.33 | L26: 9.36 | M26: 9.4 | N26: 12.24
A27: 45877 | B27: 0.93 | C27: 2.65 | D27: 3.06 | E27: 4.75 | F27: 5.46 | G27: 5.86 | H27: 6.72 | I27: 7.07 | J27: 7.76 | K27: 8.33 | L27: 9.38 | M27: 9.4 | N27: 12.28
A28: 45880 | B28: 0.92 | C28: 2.64 | D28: 3.06 | E28: 4.74 | F28: 5.45 | G28: 5.85 | H28: 6.71 | I28: 7.06 | J28: 7.75 | K28: 8.33 | L28: 9.37 | M28: 9.41 | N28: 12.31
A29: 45881 | B29: 0.96 | C29: 2.72 | D29: 3.14 | E29: 4.89 | F29: 5.61 | G29: 6.05 | H29: 6.9 | I29: 7.07 | J29: 8.02 | K29: 8.62 | L29: 9.65 | M29: 9.73 | N29: 12.73
A30: 45882 | B30: 0.95 | C30: 2.72 | D30: 3.14 | E30: 4.89 | F30: 5.62 | G30: 6.03 | H30: 6.9 | I30: 7.08 | J30: 8.03 | K30: 8.64 | L30: 9.67 | M30: 9.73 | N30: 12.73
A31: 45883 | B31: 0.95 | C31: 2.71 | D31: 3.13 | E31: 4.89 | F31: 5.61 | G31: 6.05 | H31: 6.89 | I31: 7.06 | J31: 8.02 | K31: 8.62 | L31: 9.66 | M31: 9.73 | N31: 12.62
A32: 45884 | B32: 0.95 | C32: 2.71 | D32: 3.13 | E32: 4.88 | F32: 5.61 | G32: 6.04 | H32: 6.89 | I32: 7.06 | J32: 8.01 | K32: 8.62 | L32: 9.65 | M32: 9.72 | N32: 12.6
A33: 45887 | B33: 0.98 | C33: 2.81 | D33: 3.25 | E33: 5.12 | F33: 5.9 | G33: 6.37 | H33: 7.29 | I33: 7.48 | J33: 8.52 | K33: 9.17 | L33: 10.27 | M33: 10.35 | N33: 13.4
A34: 45888 | B34: 0.94 | C34: 2.7 | D34: 3.12 | E34: 4.87 | F34: 5.6 | G34: 6.02 | H34: 6.87 | I34: 7.03 | J34: 7.98 | K34: 8.58 | L34: 9.61 | M34: 9.69 | N34: 12.53
A35: 45889 | B35: 0.93 | C35: 2.7 | D35: 3.11 | E35: 4.86 | F35: 5.59 | G35: 6.02 | H35: 6.87 | I35: 7.03 | J35: 7.97 | K35: 8.57 | L35: 9.6 | M35: 9.68 | N35: 12.51
A36: 45890 | B36: 0.93 | C36: 2.69 | D36: 3.11 | E36: 4.86 | F36: 5.58 | G36: 6.01 | H36: 6.86 | I36: 7.02 | J36: 7.96 | K36: 8.55 | L36: 9.58 | M36: 9.66 | N36: 12.46
A37: 45891 | B37: 0.93 | C37: 2.69 | D37: 3.11 | E37: 4.86 | F37: 5.59 | G37: 6.02 | H37: 6.86 | I37: 7.03 | J37: 7.97 | K37: 8.58 | L37: 9.61 | M37: 9.71 | N37: 12.55
... A69: 45937 | B69: 0.81 | C69: 2.56 | D69: 2.98 | E69: 4.75 | F69: 5.48 | G69: 5.92 | H69: 6.76 | I69: 6.93 | J69: 7.89 | K69: 8.49 | L69: 9.53 | M69: 9.61 | N69: 12.54
A70: 45938
A71: 45939 | B71: 0.8 | C71: 2.56 | D71: 2.98 | E71: 4.74 | F71: 5.48 | G71: 5.91 | H71: 6.75 | I71: 6.92 | J71: 7.87 | K71: 8.47 | L71: 9.51 | M71: 9.59 | N71: 12.49
A72: 45940 | B72: 0.8 | C72: 2.55 | D72: 2.98 | E72: 4.74 | F72: 5.47 | G72: 5.91 | H72: 6.74 | I72: 6.91 | J72: 7.86 | K72: 8.46 | L72: 9.49 | M72: 9.57 | N72: 12.45
A73: 45943 | B73: 0.79 | C73: 2.55 | D73: 2.97 | E73: 4.73 | F73: 5.46 | G73: 5.9 | H73: 6.73 | I73: 6.9 | J73: 7.85 | K73: 8.45 | L73: 9.49 | M73: 9.56 | N73: 12.45
A74: 45944 | B74: 0.79 | C74: 2.54 | D74: 2.97 | E74: 4.73 | F74: 5.46 | G74: 5.89 | H74: 6.73 | I74: 6.9 | J74: 7.86 | K74: 8.46 | L74: 9.49 | M74: 9.56 | N74: 12.46
A75: 45945 | B75: 0.79 | C75: 2.54 | D75: 2.96 | E75: 4.73 | F75: 5.46 | G75: 5.9 | H75: 6.73 | I75: 6.9 | J75: 7.86 | K75: 8.46 | L75: 9.49 | M75: 9.58 | N75: 12.5
A76: 45946 | B76: 0.78 | C76: 2.54 | D76: 2.96 | E76: 4.73 | F76: 5.46 | G76: 5.9 | H76: 6.74 | I76: 6.9 | J76: 7.85 | K76: 8.46 | L76: 9.49 | M76: 9.57 | N76: 12.49
A77: 45947 | B77: 0.78 | C77: 2.54 | D77: 2.96 | E77: 4.72 | F77: 5.46 | G77: 5.9 | H77: 6.74 | I77: 6.9 | J77: 7.85 | K77: 8.46 | L77: 9.49 | M77: 9.57 | N77: 12.49
A78: 45950 | B78: 0.77 | C78: 2.53 | D78: 2.95 | E78: 4.72 | F78: 5.45 | G78: 5.9 | H78: 6.74 | I78: 6.9 | J78: 7.85 | K78: 8.45 | L78: 9.48 | M78: 9.57 | N78: 12.49
A79: 45951 | B79: 0.77 | C79: 2.53 | D79: 2.95 | E79: 4.71 | F79: 5.45 | G79: 5.9 | H79: 6.73 | I79: 6.9 | J79: 7.86 | K79: 8.46 | L79: 9.49 | M79: 9.58 | N79: 12.53
A80: 45952 | B80: 0.77 | C80: 2.52 | D80: 2.95 | E80: 4.71 | F80: 5.45 | G80: 5.89 | H80: 6.73 | I80: 6.89 | J80: 7.84 | K80: 8.45 | L80: 9.49 | M80: 9.57 | N80: 12.52
A81: 45953 | B81: 0.79 | C81: 2.63 | D81: 3.07 | E81: 4.94 | F81: 5.72 | G81: 6.21 | H81: 7.12 | I81: 7.32 | J81: 8.35 | K81: 9.01 | L81: 10.11 | M81: 10.19 | N81: 13.34
...

Sheet YTM MEF
A1: Fecha | B1: SB12AGO26 | C1: SB12AGO28 | D1: SB12FEB29 | E1: SB12AGO31 | F1: SB12AGO32 | G1: SB12AGO33 | H1: SB12AGO34 | I1: SB12AGO35 | J1: SB12AGO37 | K1: SB12AGO39 | L1: SB12AGO40 | M1: SB12FEB42 | N1: SB12FEB55
A2: 45748 | B2: 4.1414 | C2: 4.3 | D2: 4.6664 | E2: 5.6162 | F2: 6.0462 | G2: 6.4076 | H2: 6.6812 | J2: 7.0583 | K2: 7.2114 | L2: 7.2219 | M2: 7.145 | N2: 7.0113
A3: 45749 | B3: 4.105 | C3: 4.2636 | D3: 4.63 | E3: 5.5715 | F3: 6.0023 | G3: 6.3784 | H3: 6.6489 | J3: 7.0418 | K3: 7.1926 | L3: 7.1667 | M3: 7.0898 | N3: 6.9561
A4: 45750 | B4: 4.0654 | C4: 4.224 | D4: 4.555 | E4: 5.4351 | F4: 5.851 | G4: 6.2091 | H4: 6.4844 | J4: 6.8709 | K4: 7.0597 | L4: 7.0656 | M4: 6.99 | N4: 6.6
A5: 45751 | B5: 4.0414 | C5: 4.2 | D5: 4.51 | E5: 5.4082 | F5: 5.7971 | G5: 6.1532 | H5: 6.3966 | J5: 6.8 | K5: 7.0028 | L5: 7.0371 | M5: 6.9615 | N5: 6.5715
A6: 45754 | B6: 4.0727 | C6: 4.2313 | D6: 4.5 | E6: 5.4395 | F6: 5.851 | G6: 6.1883 | H6: 6.5168 | J6: 6.9022 | K6: 7.1364 | L6: 7.1517 | M6: 7.0631 | N6: 6.56
A7: 45755 | B7: 4.0783 | C7: 4.2369 | D7: 4.475 | E7: 5.4451 | F7: 5.8968 | G7: 6.3153 | H7: 6.5871 | J7: 7.0215 | K7: 7.2201 | L7: 7.2233 | M7: 7.2 | N7: 6.6969
A8: 45756 | B8: 4.1233 | C8: 4.2819 | D8: 4.52 | E8: 5.4687 | F8: 5.9593 | G8: 6.3703 | H8: 6.6869 | J8: 7.1214 | K8: 7.2754 | L8: 7.2788 | M8: 7.1 | N8: 6.5969
A9: 45757 | B9: 4.0953 | C9: 4.2539 | D9: 4.492 | E9: 5.4508 | F9: 5.8545 | G9: 6.3392 | H9: 6.6488 | J9: 6.9772 | K9: 7.1732 | L9: 7.1927 | M9: 7.0139 | N9: 6.5108
A10: 45758 | B10: 4.133 | C10: 4.2916 | D10: 4.5297 | E10: 5.4885 | F10: 5.8972 | G10: 6.3638 | H10: 6.647 | J10: 7.0982 | K10: 7.193 | L10: 7.18 | M10: 7.1 | N10: 6.5969
A11: 45761 | B11: 4.0314 | C11: 4.19 | D11: 4.492 | E11: 5.4568 | F11: 5.8686 | G11: 6.3703 | H11: 6.6129 | J11: 6.9575 | K11: 7.1201 | L11: 7.17 | M11: 7.09 | N11: 6.5869
A12: 45762 | B12: 4.0694 | C12: 4.228 | D12: 4.53 | E12: 5.48 | F12: 5.8419 | G12: 6.3048 | H12: 6.6219 | J12: 6.9875 | K12: 7.1764 | L12: 7.1835 | M12: 7.1035 | N12: 6.6004
A13: 45763 | B13: 4.0581 | C13: 4.2167 | D13: 4.552 | E13: 5.5 | F13: 5.88 | G13: 6.3113 | H13: 6.6365 | J13: 7.03 | K13: 7.2175 | L13: 7.2125 | M13: 7.1325 | N13: 6.6294
... A21: 45777 | B21: 4.1533 | C21: 4.1282 | D21: 4.3731 | E21: 5.3159 | F21: 5.8284 | G21: 6.2076 | H21: 6.5424 | J21: 7.046 | K21: 7.1495 | L21: 7.1575 | M21: 7.144 | N21: 6.6546
A22: 45779
A23: 45782
A24: 45783 | B24: 4.1151 | C24: 4.09 | D24: 4.42 | E24: 5.3335 | F24: 5.8174 | G24: 6.2246 | H24: 6.5861 | J24: 7.0722 | K24: 7.2237 | L24: 7.2233 | M24: 7.2071 | N24: 6.7177
A25: 45784 | B25: 4.0827 | C25: 4.0576 | D25: 4.415 | E25: 5.3011 | F25: 5.7753 | G25: 6.1676 | H25: 6.5371 | J25: 6.9979 | K25: 7.1732 | L25: 7.1618 | M25: 7.1676 | N25: 6.6782
A26: 45785 | B26: 4.0577 | C26: 4.0326 | D26: 4.39 | E26: 5.3069 | F26: 5.7823 | G26: 6.1658 | H26: 6.5562 | J26: 6.9671 | K26: 7.1726 | L26: 7.1655 | M26: 7.05 | N26: 6.5606
A27: 45786 | B27: 4.0701 | C27: 4.045 | D27: 4.3213 | E27: 5.2157 | F27: 5.6652 | G27: 6.0653 | H27: 6.4266 | J27: 6.863 | K27: 7.0596 | L27: 7.0539 | M27: 6.9 | N27: 6.4106
A28: 45789 | B28: 4.0751 | C28: 4.05 | D28: 4.3244 | E28: 5.2185 | F28: 5.6777 | G28: 6.0554 | H28: 6.3899 | J28: 6.8609 | K28: 7.0666 | L28: 7.0714 | M28: 6.9175 | N28: 6.4281
A29: 45790 | B29: 4.0751 | C29: 4.05 | D29: 4.3244 | E29: 5.2185 | F29: 5.6777 | G29: 6.0554 | H29: 6.3899 | J29: 6.8609 | K29: 7.0666 | L29: 7.0714 | M29: 6.9175 | N29: 6.4281
A30: 45791 | B30: 4.0701 | C30: 4.045 | D30: 4.29 | E30: 5.2159 | F30: 5.7056 | G30: 6.0814 | H30: 6.3734 | J30: 6.8943 | K30: 7.1048 | L30: 7.1025 | M30: 7 | N30: 6.5106
A31: 45792 | B31: 4.0701 | C31: 4.045 | D31: 4.29 | E31: 5.2159 | F31: 5.7056 | G31: 6.0814 | H31: 6.3734 | J31: 6.8943 | K31: 7.1048 | L31: 7.1025 | M31: 7 | N31: 6.5106
A32: 45793 | B32: 4.0651 | C32: 4.04 | D32: 4.29 | E32: 5.23 | F32: 5.7008 | G32: 6.1038 | H32: 6.3905 | J32: 6.9021 | K32: 7.1213 | L32: 7.1154 | M32: 7.03 | N32: 6.5406
A33: 45796 | B33: 4.0683 | C33: 4.0432 | D33: 4.27 | E33: 5.21 | F33: 5.7325 | G33: 6.1416 | H33: 6.428 | J33: 6.9406 | K33: 7.1716 | L33: 7.1714 | M33: 7.086 | N33: 6.5966
A34: 45797 | B34: 4.0681 | C34: 4.043 | D34: 4.253 | E34: 5.23 | F34: 5.7654 | G34: 6.1791 | H34: 6.4653 | J34: 6.9611 | K34: 7.2076 | L34: 7.2133 | M34: 7.1279 | N34: 6.6385
A35: 45798 | B35: 3.98 | C35: 4.0348 | D35: 4.2775 | E35: 5.2645 | F35: 5.8113 | G35: 6.2325 | H35: 6.5316 | J35: 7.0328 | K35: 7.2631 | L35: 7.2531 | M35: 7.12 | N35: 6.6306
... A42: 45807 | B42: 3.97 | C42: 3.98 | D42: 4.25 | E42: 5.2554 | F42: 5.7698 | G42: 6.1445 | H42: 6.4891 | J42: 7.0264 | K42: 7.2548 | L42: 7.254 | M42: 7.1608 | N42: 7.0174
A43: 45810
A44: 45811
A45: 45812 | B45: 4.0118 | C45: 3.96 | D45: 4.2386 | E45: 5.2319 | F45: 5.6996 | G45: 6.1218 | H45: 6.4679 | J45: 6.9964 | K45: 7.2453 | L45: 7.2169 | M45: 7.1237 | N45: 6.9803
A46: 45813 | B46: 3.8 | C46: 3.84 | D46: 4.151 | E46: 5.12 | F46: 5.6925 | G46: 6.1706 | H46: 6.5956 | J46: 7.0975 | K46: 7.2794 | L46: 7.2811 | M46: 7.1879 | N46: 7.0445
A47: 45814 | B47: 3.813 | C47: 3.853 | D47: 4.15 | E47: 5.175 | F47: 5.664 | G47: 6.1635 | H47: 6.6373 | I47: 6.8846 | J47: 7.1105 | K47: 7.2965 | L47: 7.3119 | M47: 7.2187 | N47: 7.0753
A48: 45817 | B48: 3.8023 | C48: 3.86 | D48: 4.155 | E48: 5.1725 | F48: 5.6533 | G48: 6.1442 | H48: 6.604 | I48: 6.8836 | J48: 7.0639 | K48: 7.3 | L48: 7.29 | M48: 7.1968 | N48: 7.0534
A49: 45818 | B49: 3.945 | C49: 3.9046 | D49: 4.1996 | E49: 5.177 | F49: 5.6473 | G49: 6.1307 | H49: 6.5808 | I49: 6.8929 | J49: 7.0939 | K49: 7.295 | L49: 7.3038 | M49: 7.08 | N49: 6.9366
A50: 45819 | B50: 3.9104 | C50: 3.87 | D50: 4.16 | E50: 5.1888 | F50: 5.6609 | G50: 6.1281 | H50: 6.5423 | I50: 6.8721 | J50: 7.0994 | K50: 7.2715 | L50: 7.2743 | M50: 7.0505 | N50: 6.9071
A51: 45820 | B51: 3.9012 | C51: 3.8608 | D51: 4.1508 | E51: 5.1796 | F51: 5.6145 | G51: 5.9882 | H51: 6.4047 | I51: 6.7543 | J51: 6.895 | K51: 7.0831 | L51: 7.1318 | M51: 6.908 | N51: 6.7646
A52: 45821 | B52: 3.9871 | C52: 3.9467 | D52: 4.2367 | E52: 5.2021 | F52: 5.6578 | G52: 6.0414 | H52: 6.3966 | I52: 6.7266 | J52: 6.8801 | K52: 7.0969 | L52: 7.0981 | M52: 6.8743 | N52: 6.7309
A53: 45824 | B53: 4.0161 | C53: 3.9757 | D53: 4.233 | E53: 5.23 | F53: 5.675 | G53: 6.0505 | H53: 6.397 | I53: 6.7183 | J53: 6.8878 | K53: 7.0901 | L53: 7.08 | M53: 6.8562 | N53: 6.7128
...

Sheet Peso Benchmark
A1: Fecha | B1: SB12AGO37 | C1: SB12AGO31 | D1: SB12FEB42 | E1: SB12FEB55 | F1: SB12AGO32 | G1: SB12FEB29 | H1: SB12AGO34 | I1: SB12AGO40 | J1: SB12AGO33 | K1: SB12AGO39 | L1: SB12AGO35 | M1: Cash | N1: SB12AGO26 | O1: SB12AGO28
A2: 45908 | B2: 0.1214 | C2: 0.1262 | D2: 0.0314 | E2: 0.0201 | F2: 0.1283 | G2: 0.0843 | H2: 0.1032 | I2: 0.0581 | J2: 0.1137 | K2: 0.1021 | L2: 0.0646 | M2: 0 | O2: 0.0467
A3: 45909 | B3: 0.1217 | C3: 0.1261 | D3: 0.0314 | E3: 0.0201 | F3: 0.1281 | G3: 0.0841 | H3: 0.1033 | I3: 0.0582 | J3: 0.1135 | K3: 0.102 | L3: 0.0649 | M3: 0 | O3: 0.0466
A4: 45910 | B4: 0.1221 | C4: 0.1259 | D4: 0.0315 | E4: 0.0202 | F4: 0.1279 | G4: 0.0839 | H4: 0.1033 | I4: 0.0584 | J4: 0.1132 | K4: 0.1024 | L4: 0.0646 | M4: 0 | O4: 0.0465
A5: 45911 | B5: 0.1221 | C5: 0.1258 | D5: 0.0315 | E5: 0.0202 | F5: 0.1278 | G5: 0.0838 | H5: 0.1033 | I5: 0.0584 | J5: 0.1135 | K5: 0.1024 | L5: 0.0647 | M5: 0 | O5: 0.0464
A6: 45912 | B6: 0.1219 | C6: 0.1259 | D6: 0.0315 | E6: 0.0202 | F6: 0.13 | G6: 0.0838 | H6: 0.1033 | I6: 0.0584 | J6: 0.1135 | K6: 0.1024 | L6: 0.065 | M6: 0 | O6: 0.0464
A7: 45915 | B7: 0.1222 | C7: 0.1257 | D7: 0.0315 | E7: 0.0203 | F7: 0.1276 | G7: 0.086 | H7: 0.1034 | I7: 0.0587 | J7: 0.1134 | K7: 0.1027 | L7: 0.0647 | M7: 0 | O7: 0.0463
A8: 45916
A9: 45917 | B9: 0.1221 | C9: 0.126 | D9: 0.0315 | E9: 0.0202 | F9: 0.1278 | G9: 0.0838 | H9: 0.1031 | I9: 0.0586 | J9: 0.1135 | K9: 0.1025 | L9: 0.0645 | M9: 0 | O9: 0.0464
A10: 45918 | B10: 0.1216 | C10: 0.1266 | D10: 0.0314 | E10: 0.0201 | F10: 0.1286 | G10: 0.0842 | H10: 0.1031 | I10: 0.058 | J10: 0.1135 | K10: 0.1018 | L10: 0.0645 | M10: 0 | O10: 0.0466
A11: 45919 | B11: 0.1214 | C11: 0.1267 | D11: 0.0314 | E11: 0.0201 | F11: 0.1285 | G11: 0.0842 | H11: 0.103 | I11: 0.0579 | J11: 0.1136 | K11: 0.1017 | L11: 0.0647 | M11: 0 | O11: 0.0467
A12: 45922 | B12: 0.1216 | C12: 0.1266 | D12: 0.0313 | E12: 0.0201 | F12: 0.1284 | G12: 0.0841 | H12: 0.1031 | I12: 0.058 | J12: 0.1139 | K12: 0.1018 | L12: 0.0646 | M12: 0 | O12: 0.0466
A13: 45923 | B13: 0.1217 | C13: 0.1265 | D13: 0.0312 | E13: 0.0201 | F13: 0.1283 | G13: 0.0841 | H13: 0.1031 | I13: 0.058 | J13: 0.1139 | K13: 0.1018 | L13: 0.0646 | M13: 0 | O13: 0.0466
A14: 45924 | B14: 0.1217 | C14: 0.1264 | D14: 0.0313 | E14: 0.0201 | F14: 0.1282 | G14: 0.084 | H14: 0.1035 | I14: 0.0581 | J14: 0.1138 | K14: 0.1019 | L14: 0.0646 | M14: 0 | O14: 0.0465
A15: 45925 | B15: 0.1218 | C15: 0.1264 | D15: 0.0313 | E15: 0.0201 | F15: 0.1283 | G15: 0.084 | H15: 0.1031 | I15: 0.0581 | J15: 0.1139 | K15: 0.1019 | L15: 0.0646 | M15: 0 | O15: 0.0465
A16: 45926 | B16: 0.1219 | C16: 0.1263 | D16: 0.0313 | E16: 0.0201 | F16: 0.1282 | G16: 0.0841 | H16: 0.103 | I16: 0.0581 | J16: 0.1138 | K16: 0.102 | L16: 0.0645 | M16: 0 | O16: 0.0465
A17: 45929 | B17: 0.122 | C17: 0.1263 | D17: 0.0313 | E17: 0.0201 | F17: 0.1282 | G17: 0.084 | H17: 0.1031 | I17: 0.0581 | J17: 0.1138 | K17: 0.1019 | L17: 0.0646 | M17: 0 | O17: 0.0465
A18: 45930 | B18: 0.1221 | C18: 0.1262 | D18: 0.0313 | E18: 0.02 | F18: 0.1282 | G18: 0.0839 | H18: 0.1031 | I18: 0.0581 | J18: 0.1138 | K18: 0.102 | L18: 0.0647 | M18: 0 | O18: 0.0464
A19: 45931 | B19: 0.1223 | C19: 0.1261 | D19: 0.0313 | E19: 0.0201 | F19: 0.128 | G19: 0.0838 | H19: 0.1035 | I19: 0.0581 | J19: 0.1137 | K19: 0.102 | L19: 0.0648 | M19: 0 | O19: 0.0463
A20: 45932 | B20: 0.1224 | C20: 0.126 | D20: 0.0314 | E20: 0.0201 | F20: 0.1279 | G20: 0.0837 | H20: 0.1031 | I20: 0.0582 | J20: 0.1137 | K20: 0.1024 | L20: 0.0648 | M20: 0 | O20: 0.0463
... A23: 45937 | B23: 0.1223 | C23: 0.1256 | D23: 0.0316 | E23: 0.0202 | F23: 0.1277 | G23: 0.0836 | H23: 0.1031 | I23: 0.0586 | J23: 0.1137 | K23: 0.1027 | L23: 0.0646 | M23: 0 | O23: 0.0462
A24: 45938
A25: 45939 | B25: 0.1221 | C25: 0.1255 | D25: 0.0316 | E25: 0.0203 | F25: 0.1278 | G25: 0.0837 | H25: 0.103 | I25: 0.0586 | J25: 0.1138 | K25: 0.1026 | L25: 0.0646 | M25: 0 | O25: 0.0463
A26: 45940 | B26: 0.1219 | C26: 0.1256 | D26: 0.0316 | E26: 0.0203 | F26: 0.1279 | G26: 0.0838 | H26: 0.1031 | I26: 0.0585 | J26: 0.1139 | K26: 0.1025 | L26: 0.0645 | M26: 0 | O26: 0.0463
A27: 45943 | B27: 0.12 | C27: 0.1258 | D27: 0.0316 | E27: 0.0203 | F27: 0.1281 | G27: 0.0839 | H27: 0.103 | I27: 0.0585 | J27: 0.1138 | K27: 0.1025 | L27: 0.0644 | M27: 0 | O27: 0.0464
A28: 45944 | B28: 0.1217 | C28: 0.1258 | D28: 0.0316 | E28: 0.0203 | F28: 0.1281 | G28: 0.0839 | H28: 0.103 | I28: 0.0585 | J28: 0.1138 | K28: 0.1025 | L28: 0.0644 | M28: 0 | O28: 0.0464
A29: 45945 | B29: 0.1218 | C29: 0.126 | D29: 0.0315 | E29: 0.0201 | F29: 0.1282 | G29: 0.0841 | H29: 0.103 | I29: 0.0582 | J29: 0.114 | K29: 0.1021 | L29: 0.0646 | M29: 0 | O29: 0.0464
A30: 45946 | B30: 0.1218 | C30: 0.126 | D30: 0.0315 | E30: 0.0201 | F30: 0.1282 | G30: 0.0841 | H30: 0.103 | I30: 0.0582 | J30: 0.1139 | K30: 0.1022 | L30: 0.0647 | M30: 0 | O30: 0.0464
A31: 45947 | B31: 0.1218 | C31: 0.1259 | D31: 0.0315 | E31: 0.0201 | F31: 0.1282 | G31: 0.084 | H31: 0.1031 | I31: 0.0582 | J31: 0.1139 | K31: 0.1021 | L31: 0.0647 | M31: 0 | O31: 0.0464
A32: 45950 | B32: 0.1217 | C32: 0.1259 | D32: 0.0315 | E32: 0.0201 | F32: 0.1282 | G32: 0.084 | H32: 0.1032 | I32: 0.0582 | J32: 0.1139 | K32: 0.1021 | L32: 0.0648 | M32: 0 | O32: 0.0464
A33: 45951 | B33: 0.1218 | C33: 0.1258 | D33: 0.0314 | E33: 0.0201 | F33: 0.1281 | G33: 0.0839 | H33: 0.1035 | I33: 0.0581 | J33: 0.1141 | K33: 0.102 | L33: 0.0649 | M33: 0 | O33: 0.0463
A34: 45952 | B34: 0.1218 | C34: 0.1257 | D34: 0.0315 | E34: 0.0202 | F34: 0.1281 | G34: 0.0838 | H34: 0.1035 | I34: 0.0581 | J34: 0.1143 | K34: 0.102 | L34: 0.0649 | M34: 0 | O34: 0.0462
A35: 45953 | B35: 0.1217 | C35: 0.1256 | D35: 0.0315 | E35: 0.0202 | F35: 0.1281 | G35: 0.0838 | H35: 0.1035 | I35: 0.0581 | J35: 0.1145 | K35: 0.1021 | L35: 0.0648 | M35: 0 | O35: 0.0462
A36: 45954 | B36: 0.1217 | C36: 0.1255 | D36: 0.0315 | E36: 0.0202 | F36: 0.1281 | G36: 0.0838 | H36: 0.1035 | I36: 0.0582 | J36: 0.1143 | K36: 0.1022 | L36: 0.0648 | M36: 0 | O36: 0.0462
... A88: 46034 | B88: 0.1215 | C88: 0.1252 | D88: 0.0318 | E88: 0.0206 | F88: 0.1288 | G88: 0.0828 | H88: 0.1045 | I88: 0.0578 | J88: 0.1149 | K88: 0.1016 | L88: 0.0649 | M88: 0 | O88: 0.0456
A89: 46035 | B89: 0.1248 | C89: 0.0866 | D89: 0.0289 | E89: 0.0206 | F89: 0.1273 | G89: 0.0449 | H89: 0.1287 | I89: 0.0607 | J89: 0.1466 | K89: 0.1004 | L89: 0.1306
A90: 46036 | B90: 0.1213 | C90: 0.1253 | D90: 0.0319 | E90: 0.0207 | F90: 0.1288 | G90: 0.0829 | H90: 0.1045 | I90: 0.0576 | J90: 0.1149 | K90: 0.1014 | L90: 0.0649 | M90: 0 | O90: 0.0457
A91: 46037 | B91: 0.1213 | C91: 0.1253 | D91: 0.0319 | E91: 0.0207 | F91: 0.1288 | G91: 0.083 | H91: 0.1044 | I91: 0.0576 | J91: 0.1149 | K91: 0.1014 | L91: 0.0649 | M91: 0 | O91: 0.0457
A92: 46038 | B92: 0.1216 | C92: 0.1254 | D92: 0.0319 | E92: 0.0207 | F92: 0.1288 | G92: 0.083 | H92: 0.1041 | I92: 0.0578 | J92: 0.1147 | K92: 0.1015 | L92: 0.0649 | M92: 0 | O92: 0.0457
A93: 46041 | B93: 0.1217 | C93: 0.1253 | D93: 0.0319 | E93: 0.0207 | F93: 0.1287 | G93: 0.083 | H93: 0.1041 | I93: 0.0578 | J93: 0.1146 | K93: 0.1017 | L93: 0.0648 | M93: 0 | O93: 0.0457
...

Sheet Peso ETFPESOV
A1: Fecha | B1: Cash | C1: SB12AGO26 | D1: SB12AGO37 | E1: SB12AGO31 | F1: SB12FEB42 | G1: SB12FEB55 | H1: SB12AGO28 | I1: SB12AGO32 | J1: SB12FEB29 | K1: SB12AGO34 | L1: SB12AGO40 | M1: SB12AGO33 | N1: SB12AGO39 | O1: SB12AGO35
A2: 45908 | B2: 0.0025 | D2: 0.125 | E2: 0.1241 | F2: 0.0274 | G2: 0.0192 | H2: 0.0436 | I2: 0.1268 | J2: 0.0824 | K2: 0.1016 | L2: 0.0597 | M2: 0.1126 | N2: 0.1114 | O2: 0.0638
A3: 45909 | B3: 0.0023 | D3: 0.125 | E3: 0.1244 | F3: 0.0274 | G3: 0.0191 | H3: 0.0437 | I3: 0.1268 | J3: 0.0826 | K3: 0.1015 | L3: 0.0597 | M3: 0.1125 | N3: 0.1114 | O3: 0.0638
A4: 45910 | B4: 0.0023 | D4: 0.1251 | E4: 0.1241 | F4: 0.0275 | G4: 0.0191 | H4: 0.0435 | I4: 0.1265 | J4: 0.0823 | K4: 0.1016 | L4: 0.0601 | M4: 0.1123 | N4: 0.1117 | O4: 0.0639
A5: 45911 | B5: 0.0025 | D5: 0.1252 | E5: 0.124 | F5: 0.0275 | G5: 0.0192 | H5: 0.0435 | I5: 0.1264 | J5: 0.0822 | K5: 0.1017 | L5: 0.0599 | M5: 0.1122 | N5: 0.1116 | O5: 0.064
A6: 45912 | B6: 0.0025 | D6: 0.1251 | E6: 0.1241 | F6: 0.0272 | G6: 0.0192 | H6: 0.0435 | I6: 0.1268 | J6: 0.0822 | K6: 0.1015 | L6: 0.0599 | M6: 0.1124 | N6: 0.1115 | O6: 0.064
A7: 45915 | B7: 0.0025 | D7: 0.1244 | E7: 0.1249 | F7: 0.0271 | G7: 0.0191 | H7: 0.0438 | I7: 0.1274 | J7: 0.0828 | K7: 0.1015 | L7: 0.0594 | M7: 0.1124 | N7: 0.1107 | O7: 0.0639
A8: 45916
A9: 45917 | B9: 0.0025 | D9: 0.1243 | E9: 0.1252 | F9: 0.0271 | G9: 0.0193 | H9: 0.0439 | I9: 0.1274 | J9: 0.0829 | K9: 0.1013 | L9: 0.0593 | M9: 0.1126 | N9: 0.1106 | O9: 0.0637
A10: 45918 | B10: 0.0025 | D10: 0.1243 | E10: 0.1251 | F10: 0.0269 | G10: 0.0192 | H10: 0.0438 | I10: 0.1274 | J10: 0.0828 | K10: 0.1014 | L10: 0.0593 | M10: 0.113 | N10: 0.1106 | O10: 0.0638
A11: 45919 | B11: 0.0025 | D11: 0.1245 | E11: 0.1249 | F11: 0.027 | G11: 0.0192 | H11: 0.0437 | I11: 0.1273 | J11: 0.0826 | K11: 0.1014 | L11: 0.0594 | M11: 0.1128 | N11: 0.1107 | O11: 0.0638
A12: 45922 | B12: 0.0025 | D12: 0.1245 | E12: 0.1249 | F12: 0.027 | G12: 0.0192 | H12: 0.0438 | I12: 0.1272 | J12: 0.0827 | K12: 0.1014 | L12: 0.0595 | M12: 0.1128 | N12: 0.1109 | O12: 0.0638
A13: 45923 | B13: 0.0024 | D13: 0.1247 | E13: 0.1248 | F13: 0.027 | G13: 0.0191 | H13: 0.0438 | I13: 0.1271 | J13: 0.0827 | K13: 0.1013 | L13: 0.0596 | M13: 0.1127 | N13: 0.111 | O13: 0.0638
A14: 45924 | B14: 0.0024 | D14: 0.1248 | E14: 0.1248 | F14: 0.0271 | G14: 0.0192 | H14: 0.0438 | I14: 0.1271 | J14: 0.0827 | K14: 0.1013 | L14: 0.0595 | M14: 0.1128 | N14: 0.1107 | O14: 0.0638
A15: 45925 | B15: 0.0024 | D15: 0.1248 | E15: 0.1248 | F15: 0.027 | G15: 0.0191 | H15: 0.0437 | I15: 0.1272 | J15: 0.0827 | K15: 0.1013 | L15: 0.0595 | M15: 0.1129 | N15: 0.1108 | O15: 0.0638
A16: 45926 | B16: 0.0024 | D16: 0.1248 | E16: 0.1247 | F16: 0.0271 | G16: 0.0192 | H16: 0.0436 | I16: 0.1271 | J16: 0.0826 | K16: 0.1014 | L16: 0.0595 | M16: 0.1128 | N16: 0.1109 | O16: 0.0638
A17: 45929 | B17: 0.0024 | D17: 0.125 | E17: 0.1246 | F17: 0.0271 | G17: 0.0192 | H17: 0.0435 | I17: 0.127 | J17: 0.0825 | K17: 0.1014 | L17: 0.0595 | M17: 0.1129 | N17: 0.111 | O17: 0.0639
A18: 45930 | B18: 0.0024 | D18: 0.1252 | E18: 0.1243 | F18: 0.0272 | G18: 0.0192 | H18: 0.0434 | I18: 0.1268 | J18: 0.0823 | K18: 0.1014 | L18: 0.0597 | M18: 0.1127 | N18: 0.1113 | O18: 0.064
A19: 45931 | B19: 0.0024 | D19: 0.1254 | E19: 0.1241 | F19: 0.0272 | G19: 0.0192 | H19: 0.0434 | I19: 0.1267 | J19: 0.0822 | K19: 0.1015 | L19: 0.0598 | M19: 0.1126 | N19: 0.1113 | O19: 0.0642
A20: 45932 | B20: 0.0024 | D20: 0.1253 | E20: 0.124 | F20: 0.0272 | G20: 0.0192 | H20: 0.0435 | I20: 0.1267 | J20: 0.0823 | K20: 0.1014 | L20: 0.0598 | M20: 0.1128 | N20: 0.1114 | O20: 0.064
A21: 45933 | B21: 0.0024 | D21: 0.1253 | E21: 0.124 | F21: 0.0272 | G21: 0.0192 | H21: 0.0435 | I21: 0.1267 | J21: 0.0823 | K21: 0.1014 | L21: 0.0598 | M21: 0.1128 | N21: 0.1114 | O21: 0.064
A22: 45936
A23: 45937 | B23: 0.0023 | D23: 0.125 | E23: 0.1242 | F23: 0.0271 | G23: 0.0191 | H23: 0.0436 | I23: 0.127 | J23: 0.0825 | K23: 0.1015 | L23: 0.0596 | M23: 0.1129 | N23: 0.1109 | O23: 0.064
A24: 45938
A25: 45939 | B25: 0.0023 | D25: 0.12 | E25: 0.1243 | F25: 0.0272 | G25: 0.0191 | H25: 0.0437 | I25: 0.1272 | J25: 0.0827 | K25: 0.1015 | L25: 0.0595 | M25: 0.113 | N25: 0.1108 | O25: 0.0639
A26: 45940 | B26: 0.0023 | D26: 0.1246 | E26: 0.1246 | F26: 0.0271 | G26: 0.0191 | H26: 0.0437 | I26: 0.1273 | J26: 0.0829 | K26: 0.1014 | L26: 0.0594 | M26: 0.1131 | N26: 0.1106 | O26: 0.0638
A27: 45943 | B27: 0.0023 | D27: 0.1246 | E27: 0.1246 | F27: 0.0271 | G27: 0.0191 | H27: 0.0437 | I27: 0.1273 | J27: 0.0829 | K27: 0.1014 | L27: 0.0595 | M27: 0.113 | N27: 0.1108 | O27: 0.0638
A28: 45944 | B28: 0.0023 | D28: 0.1247 | E28: 0.1245 | F28: 0.0273 | G28: 0.0192 | H28: 0.0437 | I28: 0.1273 | J28: 0.0828 | K28: 0.1013 | L28: 0.0595 | M28: 0.1129 | N28: 0.1108 | O28: 0.0638
A29: 45945 | B29: 0.0023 | D29: 0.1248 | E29: 0.1243 | F29: 0.0271 | G29: 0.0193 | H29: 0.0436 | I29: 0.1273 | J29: 0.0827 | K29: 0.1014 | L29: 0.0594 | M29: 0.1129 | N29: 0.1108 | O29: 0.0639
A30: 45946 | B30: 0.0023 | D30: 0.1245 | E30: 0.1243 | F30: 0.0271 | G30: 0.0193 | H30: 0.0436 | I30: 0.1275 | J30: 0.0827 | K30: 0.1016 | L30: 0.0594 | M30: 0.1131 | N30: 0.1107 | O30: 0.0639
A31: 45947 | B31: 0.0022 | D31: 0.1244 | E31: 0.1243 | F31: 0.0272 | G31: 0.0193 | H31: 0.0436 | I31: 0.1274 | J31: 0.0826 | K31: 0.1016 | L31: 0.0593 | M31: 0.1133 | N31: 0.1107 | O31: 0.064
A32: 45950 | B32: 0.0022 | D32: 0.1245 | E32: 0.1241 | F32: 0.0272 | G32: 0.0193 | H32: 0.0435 | I32: 0.1273 | J32: 0.0824 | K32: 0.1019 | L32: 0.0593 | M32: 0.1134 | N32: 0.1107 | O32: 0.0641
A33: 45951 | B33: 0.0022 | D33: 0.1247 | E33: 0.1239 | F33: 0.0272 | G33: 0.0194 | H33: 0.0434 | I33: 0.1272 | J33: 0.0824 | K33: 0.1019 | L33: 0.0595 | M33: 0.1133 | N33: 0.1109 | O33: 0.064
A34: 45952 | B34: 0.0022 | D34: 0.1245 | E34: 0.124 | F34: 0.0271 | G34: 0.0193 | H34: 0.0435 | I34: 0.1272 | J34: 0.0825 | K34: 0.1017 | L34: 0.0595 | M34: 0.1134 | N34: 0.1109 | O34: 0.064
A35: 45953 | B35: 0.0022 | D35: 0.1245 | E35: 0.124 | F35: 0.0272 | G35: 0.0193 | H35: 0.0435 | I35: 0.1273 | J35: 0.0825 | K35: 0.1017 | L35: 0.0595 | M35: 0.1133 | N35: 0.1109 | O35: 0.0641
A36: 45954 | B36: 0.0022 | D36: 0.1247 | E36: 0.1238 | F36: 0.0271 | G36: 0.0192 | H36: 0.0435 | I36: 0.1271 | J36: 0.0824 | K36: 0.1019 | L36: 0.0596 | M36: 0.1132 | N36: 0.1111 | O36: 0.0641
... A109: 46063 | B109: 0.0016 | D109: 0.1246 | E109: 0.0872 | F109: 0.0276 | G109: 0.0198 | H109: 0.0002 | I109: 0.128 | J109: 0.0427 | K109: 0.1284 | L109: 0.0628 | M109: 0.1434 | N109: 0.1018 | O109: 0.1319
A110: 46064 | B110: -0.0257 | D110: 0.1283 | E110: 0.091 | F110: 0.0276 | G110: 0.0198 | I110: 0.1281 | J110: 0.0463 | K110: 0.1321 | L110: 0.0627 | M110: 0.1518 | N110: 0.1057 | O110: 0.1322
A111: 46065 | B111: 0.0054 | D111: 0.1244 | E111: 0.0885 | F111: 0.0268 | G111: 0.0192 | I111: 0.1246 | J111: 0.0452 | K111: 0.1286 | L111: 0.0608 | M111: 0.1474 | N111: 0.1023 | O111: 0.1268
A112: 46066 | B112: 0.0054 | D112: 0.1243 | E112: 0.0885 | F112: 0.0268 | G112: 0.0192 | I112: 0.1246 | J112: 0.0452 | K112: 0.1286 | L112: 0.0609 | M112: 0.1475 | N112: 0.1022 | O112: 0.1269
...

Sheet Diferencia de Pesos
A1: Fecha | B1: Cash | C1: SB12AGO26 | D1: SB12AGO28 | E1: SB12AGO31 | F1: SB12AGO32 | G1: SB12AGO33 | H1: SB12AGO34 | I1: SB12AGO35 | J1: SB12AGO37 | K1: SB12AGO39 | L1: SB12AGO40 | M1: SB12FEB29 | N1: SB12FEB42 | O1: SB12FEB55
A2: ='Peso Benchmark'!A2 -> 45908 | B2: 0.0025 | D2: -0.0031 | E2: -0.0021 | F2: -0.0015 | G2: -0.0011 | H2: -0.0016 | I2: -0.0008 | J2: 0.0036 | K2: 0.0093 | L2: 0.0016 | M2: -0.0019 | N2: -0.004 | O2: -0.0009
A3: ='Peso Benchmark'!A3 -> 45909 | B3: 0.0023 | D3: -0.0029 | E3: -0.0017 | F3: -0.0013 | G3: -0.001 | H3: -0.0018 | I3: -0.0011 | J3: 0.0033 | K3: 0.0094 | L3: 0.0015 | M3: -0.0015 | N3: -0.004 | O3: -0.001
A4: ='Peso Benchmark'!A4 -> 45910 | B4: 0.0023 | D4: -0.003 | E4: -0.0018 | F4: -0.0014 | G4: -0.0009 | H4: -0.0017 | I4: -0.0007 | J4: 0.003 | K4: 0.0093 | L4: 0.0017 | M4: -0.0016 | N4: -0.004 | O4: -0.0011
A5: ='Peso Benchmark'!A5 -> 45911 | B5: 0.0025 | D5: -0.0029 | E5: -0.0018 | F5: -0.0014 | G5: -0.0013 | H5: -0.0016 | I5: -0.0007 | J5: 0.0031 | K5: 0.0092 | L5: 0.0015 | M5: -0.0016 | N5: -0.004 | O5: -0.001
A6: ='Peso Benchmark'!A6 -> 45912 | B6: 0.0025 | D6: -0.0029 | E6: -0.0018 | F6: -0.0032 | G6: -0.0011 | H6: -0.0018 | I6: -0.001 | J6: 0.0032 | K6: 0.0091 | L6: 0.0015 | M6: -0.0016 | N6: -0.0043 | O6: -0.001
A7: ='Peso Benchmark'!A7 -> 45915 | B7: 0.0025 | D7: -0.0025 | E7: -0.0008 | F7: -0.0002 | G7: -0.001 | H7: -0.0019 | I7: -0.0008 | J7: 0.0022 | K7: 0.008 | L7: 0.0007 | M7: -0.0032 | N7: -0.0044 | O7: -0.0012
A8: ='Peso Benchmark'!A8 -> 45916
A9: ='Peso Benchmark'!A9 -> 45917 | B9: 0.0025 | D9: -0.0025 | E9: -0.0008 | F9: -0.0004 | G9: -0.0009 | H9: -0.0018 | I9: -0.0008 | J9: 0.0022 | K9: 0.0081 | L9: 0.0007 | M9: -0.0009 | N9: -0.0044 | O9: -0.0009
A10: ='Peso Benchmark'!A10 -> 45918 | B10: 0.0025 | D10: -0.0028 | E10: -0.0015 | F10: -0.0012 | G10: -0.0005 | H10: -0.0017 | I10: -0.0007 | J10: 0.0027 | K10: 0.0088 | L10: 0.0013 | M10: -0.0014 | N10: -0.0045 | O10: -0.0009
A11: ='Peso Benchmark'!A11 -> 45919 | B11: 0.0025 | D11: -0.003 | E11: -0.0018 | F11: -0.0012 | G11: -0.0008 | H11: -0.0016 | I11: -0.0009 | J11: 0.0031 | K11: 0.009 | L11: 0.0015 | M11: -0.0016 | N11: -0.0044 | O11: -0.0009
A12: ='Peso Benchmark'!A12 -> 45922 | B12: 0.0025 | D12: -0.0028 | E12: -0.0017 | F12: -0.0012 | G12: -0.0011 | H12: -0.0017 | I12: -0.0008 | J12: 0.0029 | K12: 0.0091 | L12: 0.0015 | M12: -0.0014 | N12: -0.0043 | O12: -0.0009
A13: ='Peso Benchmark'!A13 -> 45923 | B13: 0.0024 | D13: -0.0028 | E13: -0.0017 | F13: -0.0012 | G13: -0.0012 | H13: -0.0018 | I13: -0.0008 | J13: 0.003 | K13: 0.0092 | L13: 0.0016 | M13: -0.0014 | N13: -0.0042 | O13: -0.001
A14: ='Peso Benchmark'!A14 -> 45924 | B14: 0.0024 | D14: -0.0027 | E14: -0.0016 | F14: -0.0011 | G14: -0.001 | H14: -0.0022 | I14: -0.0008 | J14: 0.0031 | K14: 0.0088 | L14: 0.0014 | M14: -0.0013 | N14: -0.0042 | O14: -0.0009
A15: ='Peso Benchmark'!A15 -> 45925 | B15: 0.0024 | D15: -0.0028 | E15: -0.0016 | F15: -0.0011 | G15: -0.001 | H15: -0.0018 | I15: -0.0008 | J15: 0.003 | K15: 0.0089 | L15: 0.0014 | M15: -0.0013 | N15: -0.0043 | O15: -0.001
A16: ='Peso Benchmark'!A16 -> 45926 | B16: 0.0024 | D16: -0.0029 | E16: -0.0016 | F16: -0.0011 | G16: -0.001 | H16: -0.0016 | I16: -0.0007 | J16: 0.0029 | K16: 0.0089 | L16: 0.0014 | M16: -0.0015 | N16: -0.0042 | O16: -0.0009
A17: ='Peso Benchmark'!A17 -> 45929 | B17: 0.0024 | D17: -0.003 | E17: -0.0017 | F17: -0.0012 | G17: -0.0009 | H17: -0.0017 | I17: -0.0007 | J17: 0.003 | K17: 0.0091 | L17: 0.0014 | M17: -0.0015 | N17: -0.0042 | O17: -0.0009
A18: ='Peso Benchmark'!A18 -> 45930 | B18: 0.0024 | D18: -0.003 | E18: -0.0019 | F18: -0.0014 | G18: -0.0011 | H18: -0.0017 | I18: -0.0007 | J18: 0.0031 | K18: 0.0093 | L18: 0.0016 | M18: -0.0016 | N18: -0.0041 | O18: -0.0008
A19: ='Peso Benchmark'!A19 -> 45931 | B19: 0.0024 | D19: -0.0029 | E19: -0.002 | F19: -0.0013 | G19: -0.0011 | H19: -0.002 | I19: -0.0006 | J19: 0.0031 | K19: 0.0093 | L19: 0.0017 | M19: -0.0016 | N19: -0.0041 | O19: -0.0009
A20: ='Peso Benchmark'!A20 -> 45932 | B20: 0.0024 | D20: -0.0028 | E20: -0.002 | F20: -0.0012 | G20: -0.0009 | H20: -0.0017 | I20: -0.0008 | J20: 0.0029 | K20: 0.009 | L20: 0.0016 | M20: -0.0014 | N20: -0.0042 | O20: -0.0009
... A23: ='Peso Benchmark'!A23 -> 45937 | B23: 0.0023 | D23: -0.0026 | E23: -0.0014 | F23: -0.0007 | G23: -0.0008 | H23: -0.0016 | I23: -0.0006 | J23: 0.0027 | K23: 0.0082 | L23: 0.001 | M23: -0.0011 | N23: -0.0045 | O23: -0.0011
A24: ='Peso Benchmark'!A24 -> 45938
A25: ='Peso Benchmark'!A25 -> 45939 | B25: 0.0023 | D25: -0.0026 | E25: -0.0012 | F25: -0.0006 | G25: -0.0008 | H25: -0.0015 | I25: -0.0007 | J25: -0.0021 | K25: 0.0082 | L25: 0.0009 | M25: -0.001 | N25: -0.0044 | O25: -0.0012
A26: ='Peso Benchmark'!A26 -> 45940 | B26: 0.0023 | D26: -0.0026 | E26: -0.001 | F26: -0.0006 | G26: -0.0008 | H26: -0.0017 | I26: -0.0007 | J26: 0.0027 | K26: 0.0081 | L26: 0.0009 | M26: -0.0009 | N26: -0.0045 | O26: -0.0012
A27: ='Peso Benchmark'!A27 -> 45943 | B27: 0.0023 | D27: -0.0027 | E27: -0.0012 | F27: -0.0008 | G27: -0.0008 | H27: -0.0016 | I27: -0.0006 | J27: 0.0046 | K27: 0.0083 | L27: 0.001 | M27: -0.001 | N27: -0.0045 | O27: -0.0012
A28: ='Peso Benchmark'!A28 -> 45944 | B28: 0.0023 | D28: -0.0027 | E28: -0.0013 | F28: -0.0008 | G28: -0.0009 | H28: -0.0017 | I28: -0.0006 | J28: 0.003 | K28: 0.0083 | L28: 0.001 | M28: -0.0011 | N28: -0.0043 | O28: -0.0011
A29: ='Peso Benchmark'!A29 -> 45945 | B29: 0.0023 | D29: -0.0028 | E29: -0.0017 | F29: -0.0009 | G29: -0.0011 | H29: -0.0016 | I29: -0.0007 | J29: 0.003 | K29: 0.0087 | L29: 0.0012 | M29: -0.0014 | N29: -0.0044 | O29: -0.0008
A30: ='Peso Benchmark'!A30 -> 45946 | B30: 0.0023 | D30: -0.0028 | E30: -0.0017 | F30: -0.0007 | G30: -0.0008 | H30: -0.0014 | I30: -0.0008 | J30: 0.0027 | K30: 0.0085 | L30: 0.0012 | M30: -0.0014 | N30: -0.0044 | O30: -0.0008
A31: ='Peso Benchmark'!A31 -> 45947 | B31: 0.0022 | D31: -0.0028 | E31: -0.0016 | F31: -0.0008 | G31: -0.0006 | H31: -0.0015 | I31: -0.0007 | J31: 0.0026 | K31: 0.0086 | L31: 0.0011 | M31: -0.0014 | N31: -0.0043 | O31: -0.0008
A32: ='Peso Benchmark'!A32 -> 45950 | B32: 0.0022 | D32: -0.0029 | E32: -0.0018 | F32: -0.0009 | G32: -0.0005 | H32: -0.0013 | I32: -0.0007 | J32: 0.0028 | K32: 0.0086 | L32: 0.0011 | M32: -0.0016 | N32: -0.0043 | O32: -0.0008
A33: ='Peso Benchmark'!A33 -> 45951 | B33: 0.0022 | D33: -0.0029 | E33: -0.0019 | F33: -0.0009 | G33: -0.0008 | H33: -0.0016 | I33: -0.0009 | J33: 0.0029 | K33: 0.0089 | L33: 0.0014 | M33: -0.0015 | N33: -0.0042 | O33: -0.0007
A34: ='Peso Benchmark'!A34 -> 45952 | B34: 0.0022 | D34: -0.0027 | E34: -0.0017 | F34: -0.0009 | G34: -0.0009 | H34: -0.0018 | I34: -0.0009 | J34: 0.0027 | K34: 0.0089 | L34: 0.0014 | M34: -0.0013 | N34: -0.0044 | O34: -0.0009
A35: ='Peso Benchmark'!A35 -> 45953 | B35: 0.0022 | D35: -0.0027 | E35: -0.0016 | F35: -0.0008 | G35: -0.0012 | H35: -0.0018 | I35: -0.0007 | J35: 0.0028 | K35: 0.0088 | L35: 0.0014 | M35: -0.0013 | N35: -0.0043 | O35: -0.0009
A36: ='Peso Benchmark'!A36 -> 45954 | B36: 0.0022 | D36: -0.0027 | E36: -0.0017 | F36: -0.001 | G36: -0.0011 | H36: -0.0016 | I36: -0.0007 | J36: 0.003 | K36: 0.0089 | L36: 0.0014 | M36: -0.0014 | N36: -0.0044 | O36: -0.001
... A109: ='Peso Benchmark'!A109 -> 46063 | B109: 0.0016 | D109: 0.0002 | E109: 0.0006 | F109: 0.0012 | G109: -0.0035 | H109: 0.0003 | I109: 0.0025 | J109: 0.0002 | K109: -0.0019 | L109: 0.0019 | M109: -0.0019 | N109: -0.0009 | O109: -0.0003
A110: ='Peso Benchmark'!A110 -> 46064 | B110: -0.0257 | E110: 0.0043 | F110: 0.0012 | G110: 0.005 | H110: 0.0041 | I110: 0.0028 | J110: 0.004 | K110: 0.0019 | L110: 0.0018 | M110: 0.0017 | N110: -0.001 | O110: -0.0004
A111: ='Peso Benchmark'!A111 -> 46065 | B111: 0.0054 | E111: 0.0019 | F111: -0.0024 | G111: 0.0005 | H111: 0.0006 | I111: -0.0026 | J111: 0.0001 | K111: -0.0014 | L111: -0.0001 | M111: 0.0006 | N111: -0.0018 | O111: -0.001
A112: ='Peso Benchmark'!A112 -> 46066 | B112: -0.026 | E112: 0.0044 | F112: 0.0011 | G112: 0.0052 | H112: 0.0041 | I112: 0.0029 | J112: 0.0039 | K112: 0.0019 | L112: 0.0018 | M112: 0.0018 | N112: -0.0009 | O112: -0.0004
A113: ='Peso Benchmark'!A113 -> 46069 | B113: -0.026 | E113: 0.0044 | F113: 0.0012 | G113: 0.0051 | H113: 0.0042 | I113: 0.0028 | J113: 0.004 | K113: 0.002 | L113: 0.0018 | M113: 0.0018 | N113: -0.0009 | O113: -0.0004
A114: ='Peso Benchmark'!A114 -> 46070 | B114: -0.026 | E114: 0.0043 | F114: 0.0011 | G114: 0.0051 | H114: 0.0042 | I114: 0.003 | J114: 0.004 | K114: 0.002 | L114: 0.0018 | M114: 0.0017 | N114: -0.0009 | O114: -0.0004
...

Sheet Precios
A1: Fecha | B1: SB12AGO26 | C1: SB12AGO37 | D1: SB12AGO31 | E1: SB12FEB42 | F1: SB12FEB55 | G1: SB12AGO28 | H1: SB12AGO32 | I1: SB12FEB29 | J1: SB12AGO34 | K1: SB12AGO40 | L1: SB12AGO33 | M1: SB12AGO39 | N1: SB12AGO35
A2: 45748 | B2: -0.00076023758 | C2: 0.00093354971 | D2: 0.002041015 | E2: -0.0014203684 | F2: 0.0066413987 | G2: -0.0010054605 | H2: 0.0023358947 | I2: 0.00015041109 | J2: 0.0010875685 | K2: 6.5096946e-05 | L2: 0.0024657838 | M2: -0.0012034843
A3: 45749 | B3: -0.00010068226 | C3: 0.0038248953 | D3: 0.0023891034 | E3: 0.0053344723 | F3: 0.0068755695 | G3: -4.7031424e-05 | H3: 0.0023423765 | I3: 0.0012155603 | J3: 0.0026989754 | K3: 0.0053448347 | L3: 0.0021069793 | M3: 0.0028752362
A4: 45750 | B4: 0.00087488399 | C4: 0.014162854 | D4: 0.0068379701 | E4: 0.011252186 | F4: 0.038928649 | G4: 0.0022406824 | H4: 0.0089073964 | I4: 0.0025324521 | J4: 0.012559858 | K4: 0.010045323 | L4: 0.010879843 | M4: 0.010382981
A5: 45751 | B5: 0.00020500516 | C5: 0.0039451146 | D5: 0.0011081599 | E5: -0.00048593866 | F5: -0.00063975559 | G5: 0.00067201589 | H5: 0.0034640875 | I5: 0.0015058991 | J5: 0.0056092547 | K5: 0.0025736054 | L5: 0.0032627113 | M5: 0.0035512013
A6: 45754 | B6: -0.00018124056 | C6: -0.011571845 | D6: -0.0016090759 | E6: -0.010712054 | F6: 0.0070250738 | G6: 0.00015288412 | H6: -0.0045264511 | I6: 0.0002429828 | J6: -0.0095099228 | K6: -0.010646888 | L6: -0.0047436935 | M6: -0.011723924
A7: 45755 | B7: 0.00021449105 | C7: -0.0048196588 | D7: -7.1320994e-05 | E7: -0.0089431702 | F7: -0.011828897 | G7: 0.00069959581 | H7: -5.6075484e-05 | I7: 0.00081927233 | J7: -0.0029518063 | K7: -0.0072895997 | L7: -0.0060677342 | M7: -0.0046066657
A8: 45756 | B8: -0.00035772472 | C8: -0.0067316496 | D8: -0.001021723 | E8: 0.0096561114 | F8: 0.012807786 | G8: -0.00064850114 | H8: -0.0025619079 | I8: 0.0011584166 | J8: -0.0071333594 | K8: 0.0094793986 | L8: -0.0013846273 | M8: -0.0016195536
A9: 45757 | B9: -0.00035595431 | C9: 0.0055674431 | D9: 0.00073439004 | E9: -1.0231906e-06 | F9: -3.9087617e-06 | G9: -0.00064798422 | H9: 0.0025645426 | I9: -0.0013947664 | J9: 0.0026719171 | K9: -0.0069768053 | L9: 0.0014213992 | M9: 0.0029601415
A10: 45758 | B10: -0.00016617116 | C10: -0.0035216523 | D10: -0.0020495943 | E10: -1.0231917e-06 | F10: -2.9315827e-06 | G10: -0.00019893159 | H10: -0.0016794139 | I10: -0.00020279495 | J10: -0.0012341068 | K10: 0.0014588024 | L10: -0.0028227729 | M10: -0.0001715709
A11: 45761 | B11: -5.6032731e-05 | C11: 0.0084182785 | D11: 0.0015942048 | E11: 0.0014427017 | F11: 0.0019094431 | G11: 0.00045050076 | H11: 0.0012890268 | I11: -0.00033806014 | J11: 0.0030147226 | K11: 0.0014939049 | L11: 0.0031816613 | M11: 0.0032006355
A12: 45762 | B12: -0.00022889228 | C12: -0.0036752087 | D12: -0.0012069603 | E12: -0.00057829277 | F12: -0.00076953913 | G12: -0.00034804275 | H12: 0.0014103956 | I12: -0.0013203093 | J12: -0.0010160596 | K12: -0.00055877913 | L12: 0.00048612567 | M12: -0.0022236872
A13: 45763 | B13: -0.00028119348 | C13: -0.0015834898 | D13: -0.00053552816 | E13: -0.00182789 | F13: -0.0024285017 | G13: -0.00047485431 | H13: -0.0016354451 | I13: -0.00082223036 | J13: -0.00065696354 | K13: -0.0038776477 | L13: -0.00042386103 | M13: -0.0024174131
... A65: 45840 | B65: -0.00010523395 | C65: -0.0017558032 | D65: 0.0031809357 | E65: -0.003868562 | F65: 0 | G65: -5.5109387e-05 | H65: 0.0031548271 | I65: 0.0017131467 | J65: 0.0029492082 | K65: -0.00094560886 | L65: 0.0030086137 | M65: 0.00017652566
A66: 45841 | B66: -0.00074030311 | C66: -0.0015909571 | D66: 0.0025306346 | E66: 0.00048333489 | F66: -0.0031217545 | G66: -0.0025837452 | H66: 0.0011019209 | I66: -0.00027776803 | J66: -0.001185683 | K66: -0.0033430704 | L66: -0.002077341 | M66: -0.0037138949 | N66: 0.00037023074
A67: 45842 | B67: 0 | C67: 0.0017380869 | D67: 0.00089714449 | E67: 0 | F67: -0.0043560778 | G67: -0.00047388349 | H67: -0.00020205305 | I67: -3.698281e-05 | J67: 0.00066148434 | K67: 0.0022315111 | L67: -0.00026993023 | M67: 0.002288847 | N67: 0.0022340906
A68: 45845 | B68: 0 | C68: -0.0028613455 | D68: 0.00057321969 | E68: -9.9403579e-07 | F68: -0.0012430862 | G68: -0.00015834838 | H68: -0.0010306788 | I68: -0.00011000422 | J68: -0.0012431474 | K68: -0.0018367809 | L68: -0.0013664903 | M68: -0.0022967822 | N68: -0.0029927159
A69: 45846 | B69: 0 | C69: -0.0011669266 | D69: 0.0018774049 | E69: -0.0038608388 | F69: 0.0006233319 | G69: 0.001447852 | H69: 0.0012195944 | I69: 0.0016862847 | J69: -0.00032777313 | K69: 0.00019056304 | L69: 0.0010182506 | M69: 0.00080096568 | N69: -0.0021439326
A70: 45847 | B70: 0 | C70: 0.0045104865 | D70: 0.00074390941 | E70: 0.0038748048 | F70: 1.0145661e-06 | G70: -0.0022486462 | H70: 0.0024516124 | I70: -0.00031245059 | J70: 0.0014496329 | K70: 0.0053908545 | L70: 0.0017917997 | M70: 0.0042925648 | N70: 0.0015302404
A71: 45848 | B71: 0 | C71: -0.00053293917 | D71: -0.00070969157 | E71: 0 | F71: -0.0018637561 | G71: -0.00095381903 | H71: -0.0012717591 | I71: -0.00047355795 | J71: -0.0011464473 | K71: 0.00057897888 | L71: -0.00093405413 | M71: 0.0024357133 | N71: -0.0019710811
A72: 45849 | B72: -0.00077579965 | C72: -0.0022998326 | D72: 0.0019020495 | E72: -0.002896626 | F72: 0.00062207323 | G72: 0.00028163117 | H72: 0.0021633019 | I72: 0.00034491352 | J72: -0.0014028217 | K72: -0.0030477567 | L72: 0.00027809974 | M72: -0.0044733293 | N72: -0.0015745497
A73: 45852 | B73: -3.5454333e-05 | C73: 0.00098032171 | D73: -0.00014813092 | E73: -0.00096502387 | F73: -0.00061863901 | G73: 0.00058750492 | H73: 0.00016110626 | I73: 0.00074074004 | J73: -0.00063854197 | K73: -0.0012156035 | L73: -0.00052495023 | M73: -0.00075532462 | N73: -0.0012847379
A74: 45853 | B74: -0.00020698398 | C74: -0.0055212003 | D74: -0.00085528738 | E74: 0.00096595604 | F74: 0.0018692634 | G74: -0.00033016023 | H74: -0.0027220655 | I74: -0.0003577909 | J74: -0.0041251877 | K74: -0.0040690015 | L74: -0.0032419434 | M74: -0.0040248618 | N74: -0.0041158666
A75: 45854 | B75: -9.5845757e-07 | C75: -0.0034428411 | D75: 0.00055764077 | E75: -0.0051311755 | F75: -0.00062192525 | G75: 0.00022612186 | H75: 0.00018459426 | I75: 0.00028122204 | J75: -0.0021570374 | K75: -0.0027581197 | L75: -0.00028090919 | M75: -0.0024816917 | N75: -0.0011540422
A76: 45855 | B76: -0.00010447198 | C76: -0.0035827251 | D76: -0.00062279125 | E76: -0.0016033076 | F76: -0.0006202819 | G76: -5.253096e-05 | H76: -0.00075073704 | I76: -3.7864374e-05 | J76: -0.000210431 | K76: -0.0040205563 | L76: -0.00087510353 | M76: -0.002871124 | N76: -0.0017985541
A77: 45856 | B77: -5.2720725e-05 | C77: -0.0015921839 | D77: -0.00092703616 | E77: 0.0096955147 | F77: -0.003100287 | G77: 8.7243499e-05 | H77: -0.001688263 | I77: 0.00012117058 | J77: -0.0013638374 | K77: -0.0040474033 | L77: -0.0013115074 | M77: -0.004556347 | N77: -0.0021631329
... A86: 45874 | B86: -0.00078776801 | C86: 0.0015071133 | D86: -0.00024790552 | E86: 0 | F86: 0.0018846543 | G86: -0.0004633025 | H86: -0.00056100258 | I86: 2.8396452e-06 | J86: 0.003138194 | K86: 0.004444357 | L86: 0.00014480531 | M86: 0.0042530638 | N86: 0.0036488934
A87: 45875
A88: 45876 | B88: -0.00019877776 | C88: 0.0041314844 | D88: -4.3598591e-05 | E88: 0.0092750718 | F88: 0.0082164766 | G88: -0.00024207986 | H88: 0.0015060903 | I88: 3.8808375e-05 | J88: 0.0031200007 | K88: 0.0065874649 | L88: 0.0021872453 | M88: 0.0045217323 | N88: 0.0047539854
A89: 45877 | B89: -0.00021130339 | C89: 0.0031588505 | D89: 0.00013352651 | E89: -0.00051114482 | F89: 9.9190801e-07 | G89: -5.2557189e-05 | H89: -0.00070274002 | I89: -0.00019687387 | J89: 0.0024454446 | K89: 0.0027854164 | L89: -7.4505696e-05 | M89: 0.0021126271 | N89: 0.0025255094
