Workbook

Sheet Fondos
A1: ID | B1: Fondo | C1: Administradora | D1: Horizonte | E1: Fecha Inicio
A2: BBVACASH | B2: BBVA CASH SOLES BBVA SAF | C2: BBVA SAF | D2: MCP | E2: 39784
A3: BBVARENTACORTOPLAZO | B3: BBVA RENTA CORTO PLAZO S/. BBVA SAF | C3: BBVA SAF | D3: CP | E3: 38713
A4: BBVATESORERIASOLES | B4: BBVA TESORERIA SOLES FMIV BBVA SAF | C4: BBVA SAF | D4: CP | E4: 43376
A5: CREDCONSERCORTOPLAZO | B5: CRED. CONSER. CORTO PLAZO S/ CREDICORP SAF | C5: CREDICORP SAF | D5: CP | E5: 41680
A6: CREDCONSERVADLIQUIDEZ | B6: CRED. CONSERVAD. LIQUIDEZ S/ CREDICORP SAF | C6: CREDICORP SAF | D6: MCP | E6: 36622
A7: SFLiquidez | B7: SF Liquidez S/. SCOTIA FONDOS | C7: SCOTIA FONDOS | D7: MCP | E7: 44956
A8: SURACORTOPLAZOSOLES | B8: SURA CORTO PLAZO SOLES FONDOS SURA SAF | C8: FONDOS SURA SAF | D8: CP | E8: 39897
A9: SURAULTRACASHSOLES | B9: SURA ULTRA CASH SOLES FONDOS SURA SAF | C9: FONDOS SURA SAF | D9: MCP | E9: 41038
A10: BBVARENTAMEDPLAZO | B10: BBVA RENTA MED. PLAZO S/. BBVA SAF | C10: BBVA SAF | D10: MP | E10: 35720
A11: CCMEDPLAZO | B11: CC CONSERV. MED. PLAZO S/. CREDICORP SAF | C11: CREDICORP SAF | D11: MP | E11: 39150
A12: IFMEDIANOPLAZO | B12: IF MEDIANO PLAZO SOLES INTERFONDO | C12: INTERFONDO | D12: MP | E12: 37329
A13: SURARENTASOLES | B13: SURA RENTA SOLES FONDOS SURA SAF | C13: FONDOS SURA SAF | D13: MP | E13: 38856
A14: ETFPESOV | B14: ETFPESOV | C14: EL DORADO | D14: ETF | E14: 45747

Sheet Data
A1: Fecha | B1: ID | C1: Valor Cuota | D1: Patrimonio | E1: Partícipes
A2: 44926 | B2: BBVACASH | C2: 144.59972 | D2: 1.7805957e+09 | E2: 71633
A3: 44926 | B3: BBVARENTACORTOPLAZO | C3: 173.7172 | D3: 2.3560769e+08 | E3: 6188
A4: 44926 | B4: BBVATESORERIASOLES | C4: 111.44878 | D4: 1.648744e+08 | E4: 191
A5: 44926 | B5: CREDCONSERCORTOPLAZO | C5: 135.21021 | D5: 4.7676765e+08 | E5: 10418
A6: 44926 | B6: CREDCONSERVADLIQUIDEZ | C6: 296.69449 | D6: 1.4978066e+09 | E6: 28520
A7: 44926 | B7: SFLiquidez
A8: 44926 | B8: SURACORTOPLAZOSOLES | C8: 167.82192 | D8: 1.8142023e+08 | E8: 827
A9: 44926 | B9: SURAULTRACASHSOLES | C9: 144.00388 | D9: 5.731377e+08 | E9: 1948
A10: 44926 | B10: BBVARENTAMEDPLAZO | C10: 317.51362 | D10: 75204729 | E10: 4096
A11: 44926 | B11: CCMEDPLAZO | C11: 177.00757 | D11: 3.2910728e+08 | E11: 5181
A12: 44926 | B12: IFMEDIANOPLAZO | C12: 186.8327 | D12: 52576790 | E12: 3251
A13: 44926 | B13: SURARENTASOLES | C13: 195.25891 | D13: 47421040 | E13: 620
A14: 45291 | B14: BBVACASH | C14: 155.05097 | D14: 1.7577186e+09 | E14: 67700
A15: 45291 | B15: BBVARENTACORTOPLAZO | C15: 187.24948 | D15: 2.2387548e+08 | E15: 4845
A16: 45291 | B16: BBVATESORERIASOLES | C16: 119.44997 | D16: 87141003 | E16: 178
A17: 45291 | B17: CREDCONSERCORTOPLAZO | C17: 145.55335 | D17: 4.772457e+08 | E17: 10554
A18: 45291 | B18: CREDCONSERVADLIQUIDEZ | C18: 318.38267 | D18: 1.640067e+09 | E18: 30709
A19: 45291 | B19: SFLiquidez | C19: 10.796559 | D19: 7.2271873e+08 | E19: 6888
... A198: 46142 | B198: CREDCONSERVADLIQUIDEZ | C198: 355.20416 | D198: 3.0877245e+09 | E198: 42706
A199: 46142 | B199: SFLiquidez | C199: 11.991466 | D199: 1.2740405e+09 | E199: 16547 | I199: 1.98 | J199: 3.17 | K199: 3.47 | L199: 4.1 | M199: 3.64 | N199: 3.76 | O199: 3.95 | P199: 4.31 | Q199: 4.53 | R199: 4.38
A200: 46142 | B200: SURACORTOPLAZOSOLES | C200: 200.90347 | D200: 2.7268767e+08 | E200: 928 | I200: - | J200: 0.82 | K200: 2.11 | L200: 3.5 | M200: 4.33 | N200: 3.12 | O200: 4.43 | P200: 4.1 | Q200: - | R200: 4.92
A201: 46142 | B201: SURAULTRACASHSOLES | C201: 173.04719 | D201: 1.4398076e+09 | E201: 2039 | I201: 2.97 | J201: 3.14 | K201: 3.16 | L201: 2.84 | M201: 2.71 | N201: 3.92 | O201: 4.08 | P201: 4.34 | Q201: 4.48 | R201: 4.4
A202: 46142 | B202: BBVARENTAMEDPLAZO | C202: 406.12916 | D202: 4.7119646e+08 | E202: 8591 | I202: - | J202: 3.73 | K202: 4.15 | L202: 4.11 | M202: 4.6 | N202: 2.96 | O202: 3.47 | P202: - | Q202: 3.52 | R202: 3.85
A203: 46142 | B203: CCMEDPLAZO | C203: 223.68921 | D203: 8.0865092e+08 | E203: 7994 | I203: 2.94 | J203: 3.93 | K203: 4.23 | L203: 4.37 | M203: 3.96 | N203: 4.07 | O203: 4.2 | P203: 4.22 | Q203: 3.88 | R203: 3.37
A204: 46142 | B204: IFMEDIANOPLAZO | C204: 233.0134 | D204: 1.0790431e+08 | E204: 4544 | I204: 1.58 | J204: 2.99 | K204: 3.1 | L204: 3.44 | M204: 4.06 | N204: 3.73 | O204: 3.9 | P204: 4.1 | Q204: 3 | R204: 4.54
A205: 46142 | B205: SURARENTASOLES | C205: 240.5918 | D205: 1.2793668e+08 | E205: 910 | I205: - | J205: - | K205: - | L205: - | M205: - | N205: 2.92 | O205: 2.83 | P205: - | Q205: - | R205: -
A206: 46142 | B206: ETFPESOV | C206: 109.30136 | D206: 1.9400992e+08 | E206: 446 | I206: - | J206: 3.88 | K206: 3.79 | L206: 3.88 | M206: 4.34 | N206: 3.85 | O206: 4.13 | P206: 4.34 | Q206: 4.5 | R206: 4.48
A207: 46173 | B207: BBVACASH | C207: 173.16881 | D207: 2.7720311e+09 | E207: 76924 | I207: 2.12 | J207: 2.68 | K207: 2.67 | L207: 3.15 | M207: 4.87 | N207: 4.05 | O207: 4.24 | P207: 4.14 | Q207: 4.12 | R207: 4.63
A208: 46173 | B208: BBVARENTACORTOPLAZO | C208: 211.85907 | D208: 8.9365279e+08 | E208: 7233 | I208: - | J208: 4.64 | K208: 5.07 | L208: 4.69 | M208: 4.18 | N208: 3.99 | O208: 4.13 | P208: 4.43 | Q208: 4.47 | R208: 4.01
A209: 46173 | B209: BBVATESORERIASOLES | C209: 133.89353 | D209: 2.8069718e+08 | E209: 546 | I209: 0.1 | J209: 0.87 | K209: 3.04 | L209: 3.43 | M209: 3.61 | N209: 4.15 | O209: 4.48 | P209: - | Q209: 4.33 | R209: 4.33
A210: 46173 | B210: CREDCONSERCORTOPLAZO | C210: 164.40488 | D210: 1.2955914e+09 | E210: 13608 | I210: 4.07 | J210: 4.47 | K210: 4.31 | L210: 4.4 | M210: - | N210: 3.87 | O210: 4.22 | P210: 4.33 | Q210: 4.62 | R210: 4.48
A211: 46173 | B211: CREDCONSERVADLIQUIDEZ | C211: 356.45456 | D211: 3.1117907e+09 | E211: 43571 | I211: - | J211: - | K211: 3.08 | L211: 4 | M211: 3.98 | N211: - | O211: - | P211: - | Q211: - | R211: -
A212: 46173 | B212: SFLiquidez | C212: 12.034792 | D212: 1.2187905e+09 | E212: 16642 | I212: 2.31 | J212: 2.85 | K212: 2.16 | L212: 3.97 | M212: 4.6 | N212: - | O212: - | P212: - | Q212: - | R212: 5.18
A213: 46173 | B213: SURACORTOPLAZOSOLES | C213: 201.68211 | D213: 2.7119357e+08 | E213: 917 | I213: - | J213: - | K213: - | L213: - | M213: - | N213: 4.03 | O213: 4.34 | P213: 4.4 | Q213: - | R213: -
A214: 46173 | B214: SURAULTRACASHSOLES | C214: 173.65543 | D214: 1.4835407e+09 | E214: 2017 | I214: - | J214: - | K214: - | L214: - | M214: - | N214: 3.6 | O214: 4.2 | P214: 4.3 | Q214: - | R214: -
A215: 46173 | B215: BBVARENTAMEDPLAZO | C215: 407.7372 | D215: 4.6039415e+08 | E215: 8504 | I215: - | J215: - | K215: - | L215: - | M215: - | N215: 3.94 | O215: 4.44 | P215: 4.44 | Q215: 4.78 | R215: 4.92
A216: 46173 | B216: CCMEDPLAZO | C216: 225.18914 | D216: 821868199 | E216: 8009 | I216: 0.5 | J216: 0.68 | K216: 4.89 | L216: 4.67 | M216: 4.66 | N216: 2.26 | O216: 4.14 | P216: 0.5 | Q216: 3.99 | R216: 4.61
A217: 46173 | B217: IFMEDIANOPLAZO | C217: 233.8266 | D217: 1.0626809e+08 | E217: 4494 | I217: 0.8 | J217: 3.45 | K217: 3.65 | L217: 3.74 | M217: 3.26 | N217: 4.3 | O217: 4.43 | P217: 4.46 | Q217: 4.63 | R217: 2.8
A218: 46173 | B218: SURARENTASOLES | C218: 241.93932 | D218: 1.2660435e+08 | E218: 900 | I218: - | J218: 4.5 | K218: 4.76 | L218: 5.07 | M218: 5.58 | N218: - | O218: - | P218: - | Q218: - | R218: 3.75
...

Sheet Hoja1
B1: Mi Base | C1: Base SMV | D1: Valor Cuota | E1: Patrimonio | F1: Partícipes
B2: BBVACASH | C2: BBVA CASH SOLES BBVA SAF | D2: =VLOOKUP(C2,Hoja2!B:Q,5,0) -> 175.83459 | E2: =VLOOKUP(C2,Hoja2!B:Q,12,0) -> 2.7054502e+09 | F2: =VLOOKUP(C2,Hoja2!B:Q,14,0) -> 75059
B3: BBVARENTACORTOPLAZO | C3: BBVA RENTA CORTO PLAZO S/. BBVA SAF | D3: =VLOOKUP(C3,Hoja2!B:Q,5,0) -> 215.18729 | E3: =VLOOKUP(C3,Hoja2!B:Q,12,0) -> 9.0160384e+08 | F3: =VLOOKUP(C3,Hoja2!B:Q,14,0) -> 7051
B4: BBVATESORERIASOLES | C4: BBVA TESORERIA SOLES FMIV BBVA SAF | D4: =VLOOKUP(C4,Hoja2!B:Q,5,0) -> 136.05661 | E4: =VLOOKUP(C4,Hoja2!B:Q,12,0) -> 3.9166551e+08 | F4: =VLOOKUP(C4,Hoja2!B:Q,14,0) -> 614
B5: CREDCONSERCORTOPLAZO | C5: CRED. CONSER. CORTO PLAZO S/ CREDICORP SAF | D5: =VLOOKUP("CREDICORP SAF-CRED. CONSER. CORTO PLAZO S/ SERIE A",Hoja2!B:Q,5,0) -> 166.77473 | E5: =VLOOKUP(C5,Hoja2!B:Q,12,0) -> 1.3128841e+09 | F5: =VLOOKUP(C5,Hoja2!B:Q,14,0) -> 13772
B6: CREDCONSERVADLIQUIDEZ | C6: CRED. CONSERVAD. LIQUIDEZ S/ CREDICORP SAF | D6: =VLOOKUP("CREDICORP SAF-CRED. CONSERVAD. LIQUIDEZ S/ SERIE A",Hoja2!B:Q,5,0) -> 361.75433 | E6: =VLOOKUP(C6,Hoja2!B:Q,12,0) -> 3.4812322e+09 | F6: =VLOOKUP(C6,Hoja2!B:Q,14,0) -> 45788
B7: SFLiquidez | C7: SF Liquidez S/. SCOTIA FONDOS | D7: =VLOOKUP(C7,Hoja2!B:Q,5,0) -> 12.225661 | E7: =VLOOKUP(C7,Hoja2!B:Q,12,0) -> 1.2528581e+09 | F7: =VLOOKUP(C7,Hoja2!B:Q,14,0) -> 17016
B8: SURACORTOPLAZOSOLES | C8: SURA CORTO PLAZO SOLES FONDOS SURA SAF | D8: =VLOOKUP("FONDOS SURA SAF-SURA CORTO PLAZO SOLES SERIE A",Hoja2!B:Q,5,0) -> 204.30919 | E8: =VLOOKUP(C8,Hoja2!B:Q,12,0) -> 1.9394846e+08 | F8: =VLOOKUP(C8,Hoja2!B:Q,14,0) -> 874
B9: SURAULTRACASHSOLES | C9: SURA ULTRA CASH SOLES FONDOS SURA SAF | D9: =VLOOKUP("FONDOS SURA SAF-SURA ULTRA CASH SOLES SERIE A",Hoja2!B:Q,5,0) -> 176.48202 | E9: =VLOOKUP(C9,Hoja2!B:Q,12,0) -> 1.6023701e+09 | F9: =VLOOKUP(C9,Hoja2!B:Q,14,0) -> 1979
B10: BBVARENTAMEDPLAZO | C10: BBVA RENTA MED. PLAZO S/. BBVA SAF | D10: =VLOOKUP(C10,Hoja2!B:Q,5,0) -> 411.62103 | E10: =VLOOKUP(C10,Hoja2!B:Q,12,0) -> 4.3828524e+08 | F10: =VLOOKUP(C10,Hoja2!B:Q,14,0) -> 8109
B11: CCMEDPLAZO | C11: CC CONSERV. MED. PLAZO S/. CREDICORP SAF | D11: =VLOOKUP("CREDICORP SAF-CC CONSERV. MED. PLAZO S/. SERIE A",Hoja2!B:Q,5,0) -> 227.19794 | E11: =VLOOKUP(C11,Hoja2!B:Q,12,0) -> 7.5878892e+08 | F11: =VLOOKUP(C11,Hoja2!B:Q,14,0) -> 8001
B12: IFMEDIANOPLAZO | C12: IF MEDIANO PLAZO SOLES INTERFONDO | D12: =VLOOKUP(C12,Hoja2!B:Q,5,0) -> 234.7717 | E12: =VLOOKUP(C12,Hoja2!B:Q,12,0) -> 86245648 | F12: =VLOOKUP(C12,Hoja2!B:Q,14,0) -> 4285
B13: SURARENTASOLES | C13: SURA RENTA SOLES FONDOS SURA SAF | D13: =VLOOKUP("FONDOS SURA SAF-SURA RENTA SOLES SERIE A",Hoja2!B:Q,5,0) -> 243.93946 | E13: =VLOOKUP(C13,Hoja2!B:Q,12,0) -> 1.1773391e+08 | F13: =VLOOKUP(C13,Hoja2!B:Q,14,0) -> 832

Sheet Hoja2
A1: Tipo Fondo | B1: Fondo Mutuo | C1: Administradora | D1: Fec. Inicio Operación | E1: Moneda Cuota | F1: Valor Cuota | G1: Variacion desde el Inicio del 2026 | H1: Rentabilidad(A) 2025 | I1: Rentabilidad(A) 2024 | J1: Rentabilidad(A) 2023 | K1: Rentabilidad(A) 2022 | L1: Rentabilidad(A) 2021 | M1: Patrimonio S/. | N1: Patrimonio % | O1: Partícipes N | P1: Partícipes % | Q1: Inf. Atrasada
A2: 01 - Renta Variable | B2: CREDICORP ACCIONES GLOBAL CREDICORP SAF | C2: CREDICORP SAF | D2: 41358 | E2: $ | F2: 245.42066 | G2: 0.1007 | H2: 0.188 | I2: 0.1326 | J2: 0.1656 | K2: -0.2041 | L2: 0.1397 | M2: 93767260 | N2: 0.0014 | O2: 2452 | P2: 0.0032 | Q2: 46311
A3: 01 - Renta Variable | B3: CREDICORP CAPITAL ACCIONES CREDICORP SAF | C3: CREDICORP SAF | D3: 39099 | E3: $ | F3: 322.37155 | G3: 0.2983 | H3: 0.5002 | I3: 0.0939 | J3: 0.228 | K3: 0.0215 | L3: -0.0644 | M3: 1.4388458e+08 | N3: 0.0022 | O3: 2128 | P3: 0.0028 | Q3: 46311
A4: 01 - Renta Variable | B4: FARO RENTA VARIABLE GLOBAL FARO CAPITAL SAFI | C4: FARO CAPITAL SAFI | D4: 43249 | E4: $ | F4: 0 | M4: 68147270 | N4: 0.001 | O4: 44 | P4: 0.0001 | Q4: 46311
A5: 01 - Renta Variable | B5: FARO CAPITAL SAFI-FARO RENTA VARIABLE GLOBAL SERIE A | C5: FARO CAPITAL SAFI | D5: 43249 | E5: $ | F5: 197.69725 | G5: 0.1161 | H5: 0.1561 | I5: 0.1276 | J5: 0.1724 | K5: -0.206 | L5: 0.1192 | O5: 3 | P5: 0 | Q5: 46311
A6: 01 - Renta Variable | B6: FARO CAPITAL SAFI-FARO RENTA VARIABLE GLOBAL SERIE B | C6: FARO CAPITAL SAFI | D6: 43249 | E6: $ | F6: 193.17448 | G6: 0.114 | H6: 0.1534 | I6: 0.1249 | J6: 0.1697 | K6: -0.208 | L6: 0.1165 | O6: 7 | P6: 0 | Q6: 46311
A7: 01 - Renta Variable | B7: FARO CAPITAL SAFI-FARO RENTA VARIABLE GLOBAL SERIE C | C7: FARO CAPITAL SAFI | D7: 43249 | E7: $ | F7: 186.39765 | G7: 0.1119 | H7: 0.1506 | I7: 0.1198 | J7: 0.1642 | K7: -0.2117 | L7: 0.1113 | O7: 34 | P7: 0 | Q7: 46311
A8: 01 - Renta Variable | B8: IF ACCIONES INTERFONDO | C8: INTERFONDO | D8: 39101 | E8: S/. | F8: 182.3275 | G8: 0.2731 | H8: 0.3395 | I8: 0.0598 | J8: 0.1398 | K8: -0.0743 | L8: 0.075 | M8: 70932353 | N8: 0.0011 | O8: 3815 | P8: 0.005 | Q8: 46311
A9: 01 - Renta Variable | B9: Promoinvest Fondo Selectivo PROMOINVEST SAF | C9: PROMOINVEST SAF | D9: 36174 | E9: $ | F9: 5.6600474 | G9: 0.2166 | H9: 0.4809 | I9: 0.0488 | J9: 0.0595 | K9: -0.0381 | L9: 0.03 | M9: 5493878.7 | N9: 0.0001 | O9: 400 | P9: 0.0005 | Q9: 46311
A10: 01 - Renta Variable | B10: SURA ACCIONES FONDOS SURA SAF | C10: FONDOS SURA SAF | D10: 39104 | E10: S/. | F10: 28.51369 | G10: 0.3342 | H10: 0.3354 | I10: 0.1 | J10: 0.202 | K10: -0.0726 | L10: 0.0576 | M10: 35786896 | N10: 0.0005 | O10: 764 | P10: 0.001 | Q10: 46311
A11: 03 - Renta Mixta Dólares | B11: SF NOTA ESTRUC XVII SCOTIA FONDOS | C11: SCOTIA FONDOS | D11: 46175 | E11: $ | F11: 110.29902 | G11: 0.1021 | M11: 62097949 | N11: 0.0009 | O11: 18 | P11: 0 | Q11: 46311
A12: 06 - Corto Plazo Soles | B12: AC CASH PLUS S/ ANDEAN CROWN SAF S.A.C. | C12: ANDEAN CROWN SAF S.A.C. | D12: 45518 | E12: S/. | F12: 0 | M12: 1230552.2 | N12: 0 | O12: 78 | P12: 0.0001 | Q12: 46311
A13: 06 - Corto Plazo Soles | B13: ANDEAN CROWN SAF S.A.C.-AC CASH PLUS S/ SERIE A | C13: ANDEAN CROWN SAF S.A.C. | D13: 45518 | E13: S/. | F13: 11.290562 | G13: -1 | H13: 0.0547 | I13: 0.0248 | O13: 75 | P13: 0.0001 | Q13: 46295
A14: 06 - Corto Plazo Soles | B14: ANDEAN CROWN SAF S.A.C.-AC CASH PLUS S/ SERIE B | C14: ANDEAN CROWN SAF S.A.C. | D14: 45518 | E14: S/. | F14: 11.096746 | G14: -1 | H14: 0.0573 | O14: 1 | P14: 0 | Q14: 46295
A15: 06 - Corto Plazo Soles | B15: Prudential Corto Plazo S/. PRUDENTIAL SAF | C15: PRUDENTIAL SAF | D15: 45386 | E15: S/. | F15: 0 | M15: 37843810 | N15: 0.0006 | O15: 333 | P15: 0.0004 | Q15: 46311
A16: 06 - Corto Plazo Soles | B16: PRUDENTIAL SAF-Prudential Corto Plazo S/. SERIE A | C16: PRUDENTIAL SAF | D16: 45386 | E16: S/. | F16: 11.505989 | G16: 0.031 | H16: 0.0405 | I16: 0.0343 | O16: 333 | P16: 0.0004 | Q16: 46311
A17: 06 - Corto Plazo Soles | B17: PRUDENTIAL SAF-Prudential Corto Plazo S/. SERIE B | C17: PRUDENTIAL SAF | D17: 45386 | E17: S/. | F17: 11.109104 | G17: -1 | H17: 0.0417 | I17: 0.0349 | O17: 1 | P17: 0 | Q17: 46055
A18: 07 - Corto Plazo Dólares | B18: Andean Crown Cash Plus $ ANDEAN CROWN SAF S.A.C. | C18: ANDEAN CROWN SAF S.A.C. | D18: 45394 | E18: $ | F18: 0 | M18: 1726033.5 | N18: 0 | O18: 93 | P18: 0.0001 | Q18: 46311
A19: 07 - Corto Plazo Dólares | B19: ANDEAN CROWN SAF S.A.C.-Andean Crown Cash Plus $ SERIE A | C19: ANDEAN CROWN SAF S.A.C. | D19: 45394 | E19: $ | F19: 11.269038 | G19: -1 | H19: 0.0515 | I19: 0.0337 | O19: 84 | P19: 0.0001 | Q19: 46295
A20: 07 - Corto Plazo Dólares | B20: ANDEAN CROWN SAF S.A.C.-Andean Crown Cash Plus $ SERIE B | C20: ANDEAN CROWN SAF S.A.C. | D20: 45394 | E20: $ | F20: 10.557894 | G20: -1 | H20: -0.0162 | I20: 0.0351 | O20: 3 | P20: 0 | Q20: 46295
A21: 07 - Corto Plazo Dólares | B21: Prudential Corto Plazo $ PRUDENTIAL SAF | C21: PRUDENTIAL SAF | D21: 45505 | E21: $ | F21: 0 | M21: 32105328 | N21: 0.0005 | O21: 267 | P21: 0.0004 | Q21: 46311
A22: 07 - Corto Plazo Dólares | B22: PRUDENTIAL SAF-Prudential Corto Plazo $ SERIE A | C22: PRUDENTIAL SAF | D22: 45505 | E22: $ | F22: 11.241484 | G22: 0.0249 | H22: 0.0313 | I22: 0.0168 | O22: 267 | P22: 0.0004 | Q22: 46311
A23: 07 - Corto Plazo Dólares | B23: PRUDENTIAL SAF-Prudential Corto Plazo $ SERIE B | C23: PRUDENTIAL SAF | D23: 45505 | E23: $ | F23: 10.881895 | G23: -1 | H23: 0.0325 | I23: 0.0173 | O23: 1 | P23: 0 | Q23: 46030
A24: 12 - Estructurado | B24: CC 24M CUP MEM $ 1 CREDICORP SAF | C24: CREDICORP SAF | D24: 46274 | E24: $ | F24: 101.11711 | G24: 0.0098 | M24: 23333844 | N24: 0.0004 | O24: 116 | P24: 0.0002 | Q24: 46311
A25: 12 - Estructurado | B25: CC 24M CUP MEM $ 2 CREDICORP SAF | C25: CREDICORP SAF | D25: 46309 | E25: $ | F25: 100.20036 | G25: 0.0003 | M25: 15503426 | N25: 0.0002 | O25: 82 | P25: 0.0001 | Q25: 46311
A26: 12 - Estructurado | B26: CC 24M CUP MEM S/ 1 CREDICORP SAF | C26: CREDICORP SAF | D26: 46273 | E26: S/. | F26: 100.3554 | G26: 0.0015 | M26: 11044471 | N26: 0.0002 | O26: 121 | P26: 0.0002 | Q26: 46311
A27: 12 - Estructurado | B27: CC 24M CUP MEM S/ 2 CREDICORP SAF | C27: CREDICORP SAF | D27: 46304 | E27: S/. | F27: 99.059314 | G27: -0.0114 | M27: 10574366 | N27: 0.0002 | O27: 112 | P27: 0.0001 | Q27: 46311
A28: 12 - Estructurado | B28: CC 3M INV GLOB 10 CREDICORP SAF | C28: CREDICORP SAF | D28: 46212 | E28: $ | F28: 100.92503 | G28: -1 | M28: 76349197 | N28: 0.0012 | O28: 225 | P28: 0.0003 | Q28: 46308
A29: 12 - Estructurado | B29: CC 3M INV GLOB 11 CREDICORP SAF | C29: CREDICORP SAF | D29: 46227 | E29: $ | F29: 100.84312 | G29: 0.0075 | M29: 51460357 | N29: 0.0008 | O29: 184 | P29: 0.0002 | Q29: 46311
A30: 12 - Estructurado | B30: CC 3M INV GLOB 12 CREDICORP SAF | C30: CREDICORP SAF | D30: 46247 | E30: $ | F30: 100.63665 | G30: 0.0053 | M30: 48688613 | N30: 0.0007 | O30: 189 | P30: 0.0002 | Q30: 46311
A31: 12 - Estructurado | B31: CC 3M INV GLOB 13 CREDICORP SAF | C31: CREDICORP SAF | D31: 46266 | E31: $ | F31: 100.48948 | G31: 0.0038 | M31: 54547353 | N31: 0.0008 | O31: 176 | P31: 0.0002 | Q31: 46311
A32: 12 - Estructurado | B32: CC 3M INV GLOB 14 CREDICORP SAF | C32: CREDICORP SAF | D32: 46281 | E32: $ | F32: 100.34779 | G32: 0.0025 | M32: 62597551 | N32: 0.001 | O32: 174 | P32: 0.0002 | Q32: 46311
A33: 12 - Estructurado | B33: CC 3M INV GLOB 15 CREDICORP SAF | C33: CREDICORP SAF | D33: 46300 | E33: $ | F33: 100.20022 | G33: 0.001 | M33: 57923219 | N33: 0.0009 | O33: 182 | P33: 0.0002 | Q33: 46311
A34: 12 - Estructurado | B34: CC 3M INV GLOB 8 CREDICORP SAF | C34: CREDICORP SAF | D34: 46177 | E34: $ | F34: 100.94238 | G34: -1 | M34: -0.11 | N34: 0 | O34: 1 | P34: 0 | Q34: 46274
A35: 12 - Estructurado | B35: CC 3M INV GLOB 9 CREDICORP SAF | C35: CREDICORP SAF | D35: 46195 | E35: $ | F35: 100.9394 | G35: -1 | M35: 62394372 | N35: 0.0009 | O35: 190 | P35: 0.0003 | Q35: 46289
... A40: 12 - Estructurado | B40: IF V CAPITAL INTERFONDO | C40: INTERFONDO | D40: 46308 | E40: S/. | F40: 100.1895 | G40: -0.0005 | M40: 32025942 | N40: 0.0005 | O40: 146 | P40: 0.0002 | Q40: 46311
A41: 14 - Renta Mixta Crecimiento Soles | B41: CRED. CRECIMIENTO VCS CREDICORP SAF | C41: CREDICORP SAF | D41: 39618 | E41: S/. | F41: 234.47232 | G41: 0.2019 | H41: 0.2258 | I41: 0.0853 | J41: 0.1561 | K41: -0.007 | L41: 0.0144 | M41: 1.6060067e+08 | N41: 0.0024 | O41: 2843 | P41: 0.0038 | Q41: 46311
A42: 17 - Renta Mixta Balanceado Dólares | B42: CRED. EQUILIBRADO CREDICORP SAF | C42: CREDICORP SAF | D42: 39150 | E42: $ | F42: 195.09674 | G42: 0.1382 | H42: 0.1932 | I42: 0.0567 | J42: 0.1281 | K42: -0.0036 | L42: -0.0317 | M42: 1.0261385e+08 | N42: 0.0016 | O42: 1391 | P42: 0.0018 | Q42: 46311
A43: 17 - Renta Mixta Balanceado Dólares | B43: IF MIXTO BALANCEADO INTERFONDO | C43: INTERFONDO | D43: 35064 | E43: $ | F43: 92.0994 | G43: 0.114 | H43: 0.2197 | I43: 0.0473 | J43: 0.1257 | K43: -0.0022 | L43: -0.0388 | M43: 66582019 | N43: 0.001 | O43: 1467 | P43: 0.0019 | Q43: 46311
A44: 18 - Renta Mixta Moderado Soles | B44: CRED. MODERADO VCS CREDICORP SAF | C44: CREDICORP SAF | D44: 39615 | E44: S/. | F44: 186.10984 | G44: 0.059 | H44: 0.1033 | I44: 0.0611 | J44: 0.0881 | K44: -0.0002 | L44: -0.0247 | M44: 58543404 | N44: 0.0009 | O44: 1344 | P44: 0.0018 | Q44: 46311
...

Sheet Hoja3
A3: Etiquetas de fila | B3: Suma de Valor Cuota | C3: Suma de Patrimonio
A4: 45946 | B4: 2582.0335 | C4: 1.2558532e+10
A5: BBVACASH | B5: 169.08254 | C5: 2.9146272e+09
A6: BBVARENTACORTOPLAZO | B6: 206.54573 | C6: 9.7219631e+08
A7: BBVARENTAMEDPLAZO | B7: 397.37436 | C7: 3.871654e+08
A8: BBVATESORERIASOLES | B8: 130.56816 | C8: 2.9678436e+08
A9: CCMEDPLAZO | B9: 219.21646 | C9: 7.2364165e+08
A10: CREDCONSERCORTOPLAZO | B10: 160.52852 | C10: 1.212088e+09
A11: CREDCONSERVADLIQUIDEZ | B11: 347.98733 | C11: 2.6510067e+09
A12: ETFPESOV | B12: 107.5995 | C12: 163282307
A13: IFMEDIANOPLAZO | B13: 229.0359 | C13: 1.0284353e+08
A14: SFLiquidez | B14: 11.73933 | C14: 1.1914545e+09
A15: SURACORTOPLAZOSOLES | B15: 196.89077 | C15: 3.1836214e+08
A16: SURARENTASOLES | B16: 236.175 | C16: 1.246272e+08
A17: SURAULTRACASHSOLES | B17: 169.28993 | C17: 1.5004529e+09
A18: 46311 | B18: 2677.1308 | C18: 1.3392643e+10
A19: BBVACASH | B19: 175.83459 | C19: 2.7054502e+09
A20: BBVARENTACORTOPLAZO | B20: 215.18729 | C20: 9.0160384e+08 | E20: Muy Corto Plazo | G20: =SUMPRODUCT(F21:F24,G21:G24)/SUM(G21:G24) -> 204.05176 | L20: =SUMPRODUCT(K21:K24,L21:L24)/SUM(L21:L24) -> 223.96817 | M20: =SUMPRODUCT(M21:M24,L21:L24)/SUM(L21:L24) -> 0.04033333
A21: BBVARENTAMEDPLAZO | B21: 411.62103 | C21: 4.3828524e+08 | E21: CREDCONSERVADLIQUIDEZ | F21: 347.74868 | G21: 2.6958358e+09 | J21: CREDCONSERVADLIQUIDEZ | K21: 361.46005 | L21: 3.4518694e+09 | M21: =K21/F21-1 -> 0.039428964
A22: BBVATESORERIASOLES | B22: 136.05661 | C22: 3.9166551e+08 | E22: SFLiquidez | F22: 11.731006 | G22: 1196654662 | J22: SFLiquidez | K22: 12.215236 | L22: 1.2494352e+09 | M22: =K22/F22-1 -> 0.041277782
A23: CCMEDPLAZO | B23: 227.19794 | C23: 7.5878892e+08 | E23: BBVACASH | F23: 168.95559 | G23: 2.9286036e+09 | J23: BBVACASH | K23: 175.68375 | L23: 2.7057482e+09 | M23: =K23/F23-1 -> 0.039822107
A24: CREDCONSERCORTOPLAZO | B24: 166.77473 | C24: 1.3128841e+09 | E24: SURAULTRACASHSOLES | F24: 169.17041 | G24: 1.5612636e+09 | J24: SURAULTRACASHSOLES | K24: 176.33114 | L24: 1.6664965e+09 | M24: =K24/F24-1 -> 0.042328512
A25: CREDCONSERVADLIQUIDEZ | B25: 361.75433 | C25: 3.4812322e+09
A26: ETFPESOV | B26: 110.9762 | C26: 1.4957643e+08 | E26: Corto Plazo | G26: =SUMPRODUCT(F27:F30,G27:G30)/SUM(G27:G30) -> 177.42128 | L26: =SUMPRODUCT(K27:K30,L27:L30)/SUM(L27:L30) -> 180.36735 | M26: =SUMPRODUCT(M27:M30,L27:L30)/SUM(L27:L30) -> 0.038881799
A27: IFMEDIANOPLAZO | B27: 234.7717 | C27: 86245648 | E27: BBVARENTACORTOPLAZO | F27: 206.46415 | G27: 9.6458152e+08 | J27: BBVARENTACORTOPLAZO | K27: 214.81612 | L27: 8.9701957e+08 | M27: =K27/F27-1 -> 0.040452367
A28: SFLiquidez | B28: 12.225661 | C28: 1.2528581e+09 | E28: BBVATESORERIASOLES | F28: 130.46581 | G28: 2.9310617e+08 | J28: BBVATESORERIASOLES | K28: 135.93526 | L28: 3.8546594e+08 | M28: =K28/F28-1 -> 0.041922488
A29: SURACORTOPLAZOSOLES | B29: 204.30919 | C29: 1.9394846e+08 | E29: CREDCONSERCORTOPLAZO | F29: 160.45289 | G29: 1.2101422e+09 | J29: CREDCONSERCORTOPLAZO | K29: 166.41806 | L29: 1.3177931e+09 | M29: =K29/F29-1 -> 0.037177071
A30: SURARENTASOLES | B30: 243.93946 | C30: 1.1773391e+08 | E30: SURACORTOPLAZOSOLES | F30: 196.71769 | G30: 3.2559922e+08 | J30: SURACORTOPLAZOSOLES | K30: 204.02862 | L30: 1.9475346e+08 | M30: =K30/F30-1 -> 0.037164575
A31: SURAULTRACASHSOLES | B31: 176.48202 | C31: 1.6023701e+09
A32: Total general | B32: 5259.1643 | C32: 2.5951175e+10
N33: =M26*(1-30%) -> 0.027217259
A39: BBVACASH | B39: 169.08254 | C39: 175.83459 | D39: =C39/B39-1 -> 0.039933468 | E39: 2.7054502e+09
A40: BBVARENTACORTOPLAZO | B40: 206.54573 | C40: 215.18729 | D40: =C40/B40-1 -> 0.041838501 | E40: 9.0160384e+08
A41: BBVARENTAMEDPLAZO | B41: 397.37436 | C41: 411.62103 | D41: =C41/B41-1 -> 0.035852013 | E41: 4.3828524e+08
A42: BBVATESORERIASOLES | B42: 130.56816 | C42: 136.05661 | D42: =C42/B42-1 -> 0.042035112 | E42: 3.9166551e+08
A43: CCMEDPLAZO | B43: 219.21646 | C43: 227.19794 | D43: =C43/B43-1 -> 0.036409134 | E43: 7.5878892e+08
A44: CREDCONSERCORTOPLAZO | B44: 160.52852 | C44: 166.77473 | D44: =C44/B44-1 -> 0.038910273 | E44: 1.3128841e+09
A45: CREDCONSERVADLIQUIDEZ | B45: 347.98733 | C45: 361.75433 | D45: =C45/B45-1 -> 0.039561758 | E45: 3.4812322e+09
A46: ETFPESOV | B46: 107.5995 | C46: 110.9762 | D46: =C46/B46-1 -> 0.031382116 | E46: 1.4957643e+08
A47: IFMEDIANOPLAZO | B47: 229.0359 | C47: 234.7717 | D47: =C47/B47-1 -> 0.025043236 | E47: 86245648
...
